[2022-01-11 21:45:02,773][Thread-1:4100][task_id:django.request][log.py:228][ERROR][Internal Server Error: /api/images/]
Traceback (most recent call last):
  File "D:\ProgramData\Anaconda3\envs\website\lib\site-packages\django\core\handlers\exception.py", line 34, in inner
    response = get_response(request)
  File "D:\ProgramData\Anaconda3\envs\website\lib\site-packages\django\core\handlers\base.py", line 115, in _get_response
    response = self.process_exception_by_middleware(e, request)
  File "D:\ProgramData\Anaconda3\envs\website\lib\site-packages\django\core\handlers\base.py", line 113, in _get_response
    response = wrapped_callback(request, *callback_args, **callback_kwargs)
  File "D:\ProgramData\Anaconda3\envs\website\lib\site-packages\django\views\decorators\csrf.py", line 54, in wrapped_view
    return view_func(*args, **kwargs)
  File "D:\ProgramData\Anaconda3\envs\website\lib\site-packages\rest_framework\viewsets.py", line 125, in view
    return self.dispatch(request, *args, **kwargs)
  File "D:\ProgramData\Anaconda3\envs\website\lib\site-packages\rest_framework\views.py", line 509, in dispatch
    response = self.handle_exception(exc)
  File "D:\ProgramData\Anaconda3\envs\website\lib\site-packages\rest_framework\views.py", line 469, in handle_exception
    self.raise_uncaught_exception(exc)
  File "D:\ProgramData\Anaconda3\envs\website\lib\site-packages\rest_framework\views.py", line 480, in raise_uncaught_exception
    raise exc
  File "D:\ProgramData\Anaconda3\envs\website\lib\site-packages\rest_framework\views.py", line 506, in dispatch
    response = handler(request, *args, **kwargs)
  File "D:\ProgramData\Anaconda3\envs\website\lib\site-packages\rest_framework\mixins.py", line 19, in create
    self.perform_create(serializer)
  File "D:\Website\minzufs.cn\minzufs\identify\viewsets.py", line 53, in perform_create
    nation1, nation2, nation3, dst, time_consuming = batch_rename.rename()
  File "D:\Website\minzufs.cn\minzufs\identify\rename.py", line 22, in rename
    file_list_save_num = len(os.listdir(self.path_save + '/save_'+label2[j]))  # 获取文件长度（个数）
FileNotFoundError: [WinError 3] 系统找不到指定的路径。: './media/upload_sort/save_miao'
[2022-01-11 21:45:02,775][Thread-1:4100][task_id:django.server][basehttp.py:154][ERROR]["POST /api/images/ HTTP/1.1" 500 19814]
[2022-01-11 21:45:43,357][Thread-1:5476][task_id:django.request][log.py:228][ERROR][Internal Server Error: /api/images/]
Traceback (most recent call last):
  File "D:\ProgramData\Anaconda3\envs\website\lib\site-packages\django\core\handlers\exception.py", line 34, in inner
    response = get_response(request)
  File "D:\ProgramData\Anaconda3\envs\website\lib\site-packages\django\core\handlers\base.py", line 115, in _get_response
    response = self.process_exception_by_middleware(e, request)
  File "D:\ProgramData\Anaconda3\envs\website\lib\site-packages\django\core\handlers\base.py", line 113, in _get_response
    response = wrapped_callback(request, *callback_args, **callback_kwargs)
  File "D:\ProgramData\Anaconda3\envs\website\lib\site-packages\django\views\decorators\csrf.py", line 54, in wrapped_view
    return view_func(*args, **kwargs)
  File "D:\ProgramData\Anaconda3\envs\website\lib\site-packages\rest_framework\viewsets.py", line 125, in view
    return self.dispatch(request, *args, **kwargs)
  File "D:\ProgramData\Anaconda3\envs\website\lib\site-packages\rest_framework\views.py", line 509, in dispatch
    response = self.handle_exception(exc)
  File "D:\ProgramData\Anaconda3\envs\website\lib\site-packages\rest_framework\views.py", line 469, in handle_exception
    self.raise_uncaught_exception(exc)
  File "D:\ProgramData\Anaconda3\envs\website\lib\site-packages\rest_framework\views.py", line 480, in raise_uncaught_exception
    raise exc
  File "D:\ProgramData\Anaconda3\envs\website\lib\site-packages\rest_framework\views.py", line 506, in dispatch
    response = handler(request, *args, **kwargs)
  File "D:\ProgramData\Anaconda3\envs\website\lib\site-packages\rest_framework\mixins.py", line 19, in create
    self.perform_create(serializer)
  File "D:\Website\minzufs.cn\minzufs\identify\viewsets.py", line 53, in perform_create
    nation1, nation2, nation3, dst, time_consuming = batch_rename.rename()
  File "D:\Website\minzufs.cn\minzufs\identify\rename.py", line 22, in rename
    file_list_save_num = len(os.listdir(self.path_save + '/save_'+label2[j]))  # 获取文件长度（个数）
FileNotFoundError: [WinError 3] 系统找不到指定的路径。: './media/upload_sort/save_miao'
[2022-01-11 21:45:43,359][Thread-1:5476][task_id:django.server][basehttp.py:154][ERROR]["POST /api/images/ HTTP/1.1" 500 19814]
[2022-01-11 21:46:43,203][Thread-1:1876][task_id:django.request][log.py:228][ERROR][Internal Server Error: /api/images/]
Traceback (most recent call last):
  File "D:\ProgramData\Anaconda3\envs\website\lib\site-packages\django\core\handlers\exception.py", line 34, in inner
    response = get_response(request)
  File "D:\ProgramData\Anaconda3\envs\website\lib\site-packages\django\core\handlers\base.py", line 115, in _get_response
    response = self.process_exception_by_middleware(e, request)
  File "D:\ProgramData\Anaconda3\envs\website\lib\site-packages\django\core\handlers\base.py", line 113, in _get_response
    response = wrapped_callback(request, *callback_args, **callback_kwargs)
  File "D:\ProgramData\Anaconda3\envs\website\lib\site-packages\django\views\decorators\csrf.py", line 54, in wrapped_view
    return view_func(*args, **kwargs)
  File "D:\ProgramData\Anaconda3\envs\website\lib\site-packages\rest_framework\viewsets.py", line 125, in view
    return self.dispatch(request, *args, **kwargs)
  File "D:\ProgramData\Anaconda3\envs\website\lib\site-packages\rest_framework\views.py", line 509, in dispatch
    response = self.handle_exception(exc)
  File "D:\ProgramData\Anaconda3\envs\website\lib\site-packages\rest_framework\views.py", line 469, in handle_exception
    self.raise_uncaught_exception(exc)
  File "D:\ProgramData\Anaconda3\envs\website\lib\site-packages\rest_framework\views.py", line 480, in raise_uncaught_exception
    raise exc
  File "D:\ProgramData\Anaconda3\envs\website\lib\site-packages\rest_framework\views.py", line 506, in dispatch
    response = handler(request, *args, **kwargs)
  File "D:\ProgramData\Anaconda3\envs\website\lib\site-packages\rest_framework\mixins.py", line 19, in create
    self.perform_create(serializer)
  File "D:\Website\minzufs.cn\minzufs\identify\viewsets.py", line 53, in perform_create
    nation1, nation2, nation3, dst, time_consuming = batch_rename.rename()
  File "D:\Website\minzufs.cn\minzufs\identify\rename.py", line 22, in rename
    file_list_save_num = len(os.listdir(self.path_save + '/save_'+label2[j]))  # 获取文件长度（个数）
FileNotFoundError: [WinError 3] 系统找不到指定的路径。: './media/upload_sort/save_miao'
[2022-01-11 21:46:43,205][Thread-1:1876][task_id:django.server][basehttp.py:154][ERROR]["POST /api/images/ HTTP/1.1" 500 19817]
[2022-01-11 21:47:19,386][Thread-1:972][task_id:django.request][log.py:228][ERROR][Internal Server Error: /api/images/]
Traceback (most recent call last):
  File "D:\ProgramData\Anaconda3\envs\website\lib\site-packages\django\core\handlers\exception.py", line 34, in inner
    response = get_response(request)
  File "D:\ProgramData\Anaconda3\envs\website\lib\site-packages\django\core\handlers\base.py", line 115, in _get_response
    response = self.process_exception_by_middleware(e, request)
  File "D:\ProgramData\Anaconda3\envs\website\lib\site-packages\django\core\handlers\base.py", line 113, in _get_response
    response = wrapped_callback(request, *callback_args, **callback_kwargs)
  File "D:\ProgramData\Anaconda3\envs\website\lib\site-packages\django\views\decorators\csrf.py", line 54, in wrapped_view
    return view_func(*args, **kwargs)
  File "D:\ProgramData\Anaconda3\envs\website\lib\site-packages\rest_framework\viewsets.py", line 125, in view
    return self.dispatch(request, *args, **kwargs)
  File "D:\ProgramData\Anaconda3\envs\website\lib\site-packages\rest_framework\views.py", line 509, in dispatch
    response = self.handle_exception(exc)
  File "D:\ProgramData\Anaconda3\envs\website\lib\site-packages\rest_framework\views.py", line 469, in handle_exception
    self.raise_uncaught_exception(exc)
  File "D:\ProgramData\Anaconda3\envs\website\lib\site-packages\rest_framework\views.py", line 480, in raise_uncaught_exception
    raise exc
  File "D:\ProgramData\Anaconda3\envs\website\lib\site-packages\rest_framework\views.py", line 506, in dispatch
    response = handler(request, *args, **kwargs)
  File "D:\ProgramData\Anaconda3\envs\website\lib\site-packages\rest_framework\mixins.py", line 19, in create
    self.perform_create(serializer)
  File "D:\Website\minzufs.cn\minzufs\identify\viewsets.py", line 53, in perform_create
    nation1, nation2, nation3, dst, time_consuming = batch_rename.rename()
  File "D:\Website\minzufs.cn\minzufs\identify\rename.py", line 22, in rename
    file_list_save_num = len(os.listdir(self.path_save + '/save_'+label2[j]))  # 获取文件长度（个数）
FileNotFoundError: [WinError 3] 系统找不到指定的路径。: './media/upload_sort/save_miao'
[2022-01-11 21:47:19,388][Thread-1:972][task_id:django.server][basehttp.py:154][ERROR]["POST /api/images/ HTTP/1.1" 500 19814]
[2022-01-11 21:48:14,319][Thread-1:1652][task_id:django.request][log.py:228][ERROR][Internal Server Error: /api/images/]
Traceback (most recent call last):
  File "D:\ProgramData\Anaconda3\envs\website\lib\site-packages\django\core\handlers\exception.py", line 34, in inner
    response = get_response(request)
  File "D:\ProgramData\Anaconda3\envs\website\lib\site-packages\django\core\handlers\base.py", line 115, in _get_response
    response = self.process_exception_by_middleware(e, request)
  File "D:\ProgramData\Anaconda3\envs\website\lib\site-packages\django\core\handlers\base.py", line 113, in _get_response
    response = wrapped_callback(request, *callback_args, **callback_kwargs)
  File "D:\ProgramData\Anaconda3\envs\website\lib\site-packages\django\views\decorators\csrf.py", line 54, in wrapped_view
    return view_func(*args, **kwargs)
  File "D:\ProgramData\Anaconda3\envs\website\lib\site-packages\rest_framework\viewsets.py", line 125, in view
    return self.dispatch(request, *args, **kwargs)
  File "D:\ProgramData\Anaconda3\envs\website\lib\site-packages\rest_framework\views.py", line 509, in dispatch
    response = self.handle_exception(exc)
  File "D:\ProgramData\Anaconda3\envs\website\lib\site-packages\rest_framework\views.py", line 469, in handle_exception
    self.raise_uncaught_exception(exc)
  File "D:\ProgramData\Anaconda3\envs\website\lib\site-packages\rest_framework\views.py", line 480, in raise_uncaught_exception
    raise exc
  File "D:\ProgramData\Anaconda3\envs\website\lib\site-packages\rest_framework\views.py", line 506, in dispatch
    response = handler(request, *args, **kwargs)
  File "D:\ProgramData\Anaconda3\envs\website\lib\site-packages\rest_framework\mixins.py", line 19, in create
    self.perform_create(serializer)
  File "D:\Website\minzufs.cn\minzufs\identify\viewsets.py", line 53, in perform_create
    nation1, nation2, nation3, dst, time_consuming = batch_rename.rename()
  File "D:\Website\minzufs.cn\minzufs\identify\rename.py", line 22, in rename
    file_list_save_num = len(os.listdir(self.path_save + '/save_'+label2[j]))  # 获取文件长度（个数）
FileNotFoundError: [WinError 3] 系统找不到指定的路径。: './media/upload_sort/save_miao'
[2022-01-11 21:48:14,321][Thread-1:1652][task_id:django.server][basehttp.py:154][ERROR]["POST /api/images/ HTTP/1.1" 500 19814]
[2022-01-11 21:50:24,722][Thread-1:3664][task_id:django.request][log.py:228][ERROR][Internal Server Error: /api/images/]
Traceback (most recent call last):
  File "D:\ProgramData\Anaconda3\envs\website\lib\site-packages\django\core\handlers\exception.py", line 34, in inner
    response = get_response(request)
  File "D:\ProgramData\Anaconda3\envs\website\lib\site-packages\django\core\handlers\base.py", line 115, in _get_response
    response = self.process_exception_by_middleware(e, request)
  File "D:\ProgramData\Anaconda3\envs\website\lib\site-packages\django\core\handlers\base.py", line 113, in _get_response
    response = wrapped_callback(request, *callback_args, **callback_kwargs)
  File "D:\ProgramData\Anaconda3\envs\website\lib\site-packages\django\views\decorators\csrf.py", line 54, in wrapped_view
    return view_func(*args, **kwargs)
  File "D:\ProgramData\Anaconda3\envs\website\lib\site-packages\rest_framework\viewsets.py", line 125, in view
    return self.dispatch(request, *args, **kwargs)
  File "D:\ProgramData\Anaconda3\envs\website\lib\site-packages\rest_framework\views.py", line 509, in dispatch
    response = self.handle_exception(exc)
  File "D:\ProgramData\Anaconda3\envs\website\lib\site-packages\rest_framework\views.py", line 469, in handle_exception
    self.raise_uncaught_exception(exc)
  File "D:\ProgramData\Anaconda3\envs\website\lib\site-packages\rest_framework\views.py", line 480, in raise_uncaught_exception
    raise exc
  File "D:\ProgramData\Anaconda3\envs\website\lib\site-packages\rest_framework\views.py", line 506, in dispatch
    response = handler(request, *args, **kwargs)
  File "D:\ProgramData\Anaconda3\envs\website\lib\site-packages\rest_framework\mixins.py", line 19, in create
    self.perform_create(serializer)
  File "D:\Website\minzufs.cn\minzufs\identify\viewsets.py", line 53, in perform_create
    nation1, nation2, nation3, dst, time_consuming = batch_rename.rename()
  File "D:\Website\minzufs.cn\minzufs\identify\rename.py", line 34, in rename
    os.rename(src, dst)
FileExistsError: [WinError 183] 当文件已存在时，无法创建该文件。: 'D:\\Website\\minzufs.cn\\minzufs\\media\\upload_images\\th.jpg' -> 'D:\\Website\\minzufs.cn\\minzufs\\media\\upload_sort\\save_miao\\miao_30.jpg'
[2022-01-11 21:50:24,724][Thread-1:3664][task_id:django.server][basehttp.py:154][ERROR]["POST /api/images/ HTTP/1.1" 500 19974]
[2022-01-11 21:51:10,442][Thread-1:3700][task_id:django.request][log.py:228][ERROR][Internal Server Error: /api/images/]
Traceback (most recent call last):
  File "D:\ProgramData\Anaconda3\envs\website\lib\site-packages\django\core\handlers\exception.py", line 34, in inner
    response = get_response(request)
  File "D:\ProgramData\Anaconda3\envs\website\lib\site-packages\django\core\handlers\base.py", line 115, in _get_response
    response = self.process_exception_by_middleware(e, request)
  File "D:\ProgramData\Anaconda3\envs\website\lib\site-packages\django\core\handlers\base.py", line 113, in _get_response
    response = wrapped_callback(request, *callback_args, **callback_kwargs)
  File "D:\ProgramData\Anaconda3\envs\website\lib\site-packages\django\views\decorators\csrf.py", line 54, in wrapped_view
    return view_func(*args, **kwargs)
  File "D:\ProgramData\Anaconda3\envs\website\lib\site-packages\rest_framework\viewsets.py", line 125, in view
    return self.dispatch(request, *args, **kwargs)
  File "D:\ProgramData\Anaconda3\envs\website\lib\site-packages\rest_framework\views.py", line 509, in dispatch
    response = self.handle_exception(exc)
  File "D:\ProgramData\Anaconda3\envs\website\lib\site-packages\rest_framework\views.py", line 469, in handle_exception
    self.raise_uncaught_exception(exc)
  File "D:\ProgramData\Anaconda3\envs\website\lib\site-packages\rest_framework\views.py", line 480, in raise_uncaught_exception
    raise exc
  File "D:\ProgramData\Anaconda3\envs\website\lib\site-packages\rest_framework\views.py", line 506, in dispatch
    response = handler(request, *args, **kwargs)
  File "D:\ProgramData\Anaconda3\envs\website\lib\site-packages\rest_framework\mixins.py", line 19, in create
    self.perform_create(serializer)
  File "D:\Website\minzufs.cn\minzufs\identify\viewsets.py", line 53, in perform_create
    nation1, nation2, nation3, dst, time_consuming = batch_rename.rename()
  File "D:\Website\minzufs.cn\minzufs\identify\rename.py", line 36, in rename
    os.rename(src, dst)
FileExistsError: [WinError 183] 当文件已存在时，无法创建该文件。: 'D:\\Website\\minzufs.cn\\minzufs\\media\\upload_images\\th.jpg' -> 'D:\\Website\\minzufs.cn\\minzufs\\media\\upload_sort\\save_miao\\miao_31.jpg'
[2022-01-11 21:51:10,444][Thread-1:3700][task_id:django.server][basehttp.py:154][ERROR]["POST /api/images/ HTTP/1.1" 500 19974]
[2022-01-11 21:52:20,308][Thread-1:13860][task_id:django.request][log.py:228][ERROR][Internal Server Error: /api/images/]
Traceback (most recent call last):
  File "D:\ProgramData\Anaconda3\envs\website\lib\site-packages\django\core\handlers\exception.py", line 34, in inner
    response = get_response(request)
  File "D:\ProgramData\Anaconda3\envs\website\lib\site-packages\django\core\handlers\base.py", line 115, in _get_response
    response = self.process_exception_by_middleware(e, request)
  File "D:\ProgramData\Anaconda3\envs\website\lib\site-packages\django\core\handlers\base.py", line 113, in _get_response
    response = wrapped_callback(request, *callback_args, **callback_kwargs)
  File "D:\ProgramData\Anaconda3\envs\website\lib\site-packages\django\views\decorators\csrf.py", line 54, in wrapped_view
    return view_func(*args, **kwargs)
  File "D:\ProgramData\Anaconda3\envs\website\lib\site-packages\rest_framework\viewsets.py", line 125, in view
    return self.dispatch(request, *args, **kwargs)
  File "D:\ProgramData\Anaconda3\envs\website\lib\site-packages\rest_framework\views.py", line 509, in dispatch
    response = self.handle_exception(exc)
  File "D:\ProgramData\Anaconda3\envs\website\lib\site-packages\rest_framework\views.py", line 469, in handle_exception
    self.raise_uncaught_exception(exc)
  File "D:\ProgramData\Anaconda3\envs\website\lib\site-packages\rest_framework\views.py", line 480, in raise_uncaught_exception
    raise exc
  File "D:\ProgramData\Anaconda3\envs\website\lib\site-packages\rest_framework\views.py", line 506, in dispatch
    response = handler(request, *args, **kwargs)
  File "D:\ProgramData\Anaconda3\envs\website\lib\site-packages\rest_framework\mixins.py", line 19, in create
    self.perform_create(serializer)
  File "D:\Website\minzufs.cn\minzufs\identify\viewsets.py", line 53, in perform_create
    nation1, nation2, nation3, dst, time_consuming = batch_rename.rename()
  File "D:\Website\minzufs.cn\minzufs\identify\rename.py", line 36, in rename
    os.rename(src, dst)
FileExistsError: [WinError 183] 当文件已存在时，无法创建该文件。: 'D:\\Website\\minzufs.cn\\minzufs\\media\\upload_images\\th.jpg' -> 'D:\\Website\\minzufs.cn\\minzufs\\media\\upload_sort\\save_miao\\miao_32.jpg'
[2022-01-11 21:52:20,310][Thread-1:13860][task_id:django.server][basehttp.py:154][ERROR]["POST /api/images/ HTTP/1.1" 500 19974]
[2022-01-11 21:56:12,059][Thread-1:10344][task_id:django.request][log.py:228][ERROR][Internal Server Error: /api/images/]
Traceback (most recent call last):
  File "D:\ProgramData\Anaconda3\envs\website\lib\site-packages\django\core\handlers\exception.py", line 34, in inner
    response = get_response(request)
  File "D:\ProgramData\Anaconda3\envs\website\lib\site-packages\django\core\handlers\base.py", line 115, in _get_response
    response = self.process_exception_by_middleware(e, request)
  File "D:\ProgramData\Anaconda3\envs\website\lib\site-packages\django\core\handlers\base.py", line 113, in _get_response
    response = wrapped_callback(request, *callback_args, **callback_kwargs)
  File "D:\ProgramData\Anaconda3\envs\website\lib\site-packages\django\views\decorators\csrf.py", line 54, in wrapped_view
    return view_func(*args, **kwargs)
  File "D:\ProgramData\Anaconda3\envs\website\lib\site-packages\rest_framework\viewsets.py", line 125, in view
    return self.dispatch(request, *args, **kwargs)
  File "D:\ProgramData\Anaconda3\envs\website\lib\site-packages\rest_framework\views.py", line 509, in dispatch
    response = self.handle_exception(exc)
  File "D:\ProgramData\Anaconda3\envs\website\lib\site-packages\rest_framework\views.py", line 469, in handle_exception
    self.raise_uncaught_exception(exc)
  File "D:\ProgramData\Anaconda3\envs\website\lib\site-packages\rest_framework\views.py", line 480, in raise_uncaught_exception
    raise exc
  File "D:\ProgramData\Anaconda3\envs\website\lib\site-packages\rest_framework\views.py", line 506, in dispatch
    response = handler(request, *args, **kwargs)
  File "D:\ProgramData\Anaconda3\envs\website\lib\site-packages\rest_framework\mixins.py", line 19, in create
    self.perform_create(serializer)
  File "D:\Website\minzufs.cn\minzufs\identify\viewsets.py", line 53, in perform_create
    nation1, nation2, nation3, dst, time_consuming = batch_rename.rename()
  File "D:\Website\minzufs.cn\minzufs\identify\rename.py", line 22, in rename
    file_list_save_num = len(os.listdir(self.path_save + '/save_'+label2[j]))  # 获取文件长度（个数）
FileNotFoundError: [WinError 3] 系统找不到指定的路径。: './media/upload_sort/save_miao'
[2022-01-11 21:56:12,060][Thread-1:10344][task_id:django.server][basehttp.py:154][ERROR]["POST /api/images/ HTTP/1.1" 500 19814]
[2022-01-11 21:57:09,615][Thread-1:10380][task_id:django.request][log.py:228][ERROR][Internal Server Error: /api/images/]
Traceback (most recent call last):
  File "D:\ProgramData\Anaconda3\envs\website\lib\site-packages\django\core\handlers\exception.py", line 34, in inner
    response = get_response(request)
  File "D:\ProgramData\Anaconda3\envs\website\lib\site-packages\django\core\handlers\base.py", line 115, in _get_response
    response = self.process_exception_by_middleware(e, request)
  File "D:\ProgramData\Anaconda3\envs\website\lib\site-packages\django\core\handlers\base.py", line 113, in _get_response
    response = wrapped_callback(request, *callback_args, **callback_kwargs)
  File "D:\ProgramData\Anaconda3\envs\website\lib\site-packages\django\views\decorators\csrf.py", line 54, in wrapped_view
    return view_func(*args, **kwargs)
  File "D:\ProgramData\Anaconda3\envs\website\lib\site-packages\rest_framework\viewsets.py", line 125, in view
    return self.dispatch(request, *args, **kwargs)
  File "D:\ProgramData\Anaconda3\envs\website\lib\site-packages\rest_framework\views.py", line 509, in dispatch
    response = self.handle_exception(exc)
  File "D:\ProgramData\Anaconda3\envs\website\lib\site-packages\rest_framework\views.py", line 469, in handle_exception
    self.raise_uncaught_exception(exc)
  File "D:\ProgramData\Anaconda3\envs\website\lib\site-packages\rest_framework\views.py", line 480, in raise_uncaught_exception
    raise exc
  File "D:\ProgramData\Anaconda3\envs\website\lib\site-packages\rest_framework\views.py", line 506, in dispatch
    response = handler(request, *args, **kwargs)
  File "D:\ProgramData\Anaconda3\envs\website\lib\site-packages\rest_framework\mixins.py", line 19, in create
    self.perform_create(serializer)
  File "D:\Website\minzufs.cn\minzufs\identify\viewsets.py", line 53, in perform_create
    nation1, nation2, nation3, dst, time_consuming = batch_rename.rename()
  File "D:\Website\minzufs.cn\minzufs\identify\rename.py", line 15, in rename
    if not os.path.exists(os.path.realpath(self.path_save + '/save_' + label2[j])):
UnboundLocalError: local variable 'j' referenced before assignment
[2022-01-11 21:57:09,617][Thread-1:10380][task_id:django.server][basehttp.py:154][ERROR]["POST /api/images/ HTTP/1.1" 500 19706]
[2022-01-11 22:10:49,856][Thread-1:10344][task_id:django.request][log.py:228][ERROR][Internal Server Error: /api/images/]
Traceback (most recent call last):
  File "D:\ProgramData\Anaconda3\envs\website\lib\site-packages\django\core\handlers\exception.py", line 34, in inner
    response = get_response(request)
  File "D:\ProgramData\Anaconda3\envs\website\lib\site-packages\django\core\handlers\base.py", line 115, in _get_response
    response = self.process_exception_by_middleware(e, request)
  File "D:\ProgramData\Anaconda3\envs\website\lib\site-packages\django\core\handlers\base.py", line 113, in _get_response
    response = wrapped_callback(request, *callback_args, **callback_kwargs)
  File "D:\ProgramData\Anaconda3\envs\website\lib\site-packages\django\views\decorators\csrf.py", line 54, in wrapped_view
    return view_func(*args, **kwargs)
  File "D:\ProgramData\Anaconda3\envs\website\lib\site-packages\rest_framework\viewsets.py", line 125, in view
    return self.dispatch(request, *args, **kwargs)
  File "D:\ProgramData\Anaconda3\envs\website\lib\site-packages\rest_framework\views.py", line 509, in dispatch
    response = self.handle_exception(exc)
  File "D:\ProgramData\Anaconda3\envs\website\lib\site-packages\rest_framework\views.py", line 469, in handle_exception
    self.raise_uncaught_exception(exc)
  File "D:\ProgramData\Anaconda3\envs\website\lib\site-packages\rest_framework\views.py", line 480, in raise_uncaught_exception
    raise exc
  File "D:\ProgramData\Anaconda3\envs\website\lib\site-packages\rest_framework\views.py", line 506, in dispatch
    response = handler(request, *args, **kwargs)
  File "D:\ProgramData\Anaconda3\envs\website\lib\site-packages\rest_framework\mixins.py", line 19, in create
    self.perform_create(serializer)
  File "D:\Website\minzufs.cn\minzufs\identify\viewsets.py", line 53, in perform_create
    nation1, nation2, nation3, dst, time_consuming = batch_rename.rename()
  File "D:\Website\minzufs.cn\minzufs\identify\rename.py", line 40, in rename
    print('数量：' + i + '张')
TypeError: can only concatenate str (not "int") to str
[2022-01-11 22:10:49,858][Thread-1:10344][task_id:django.server][basehttp.py:154][ERROR]["POST /api/images/ HTTP/1.1" 500 19637]
[2022-01-12 16:12:02,806][Thread-16:2828][task_id:django.request][log.py:228][ERROR][Internal Server Error: /api/images/54/change-nation/]
Traceback (most recent call last):
  File "D:\ProgramData\Anaconda3\envs\website\lib\site-packages\django\core\handlers\exception.py", line 34, in inner
    response = get_response(request)
  File "D:\ProgramData\Anaconda3\envs\website\lib\site-packages\django\core\handlers\base.py", line 115, in _get_response
    response = self.process_exception_by_middleware(e, request)
  File "D:\ProgramData\Anaconda3\envs\website\lib\site-packages\django\core\handlers\base.py", line 113, in _get_response
    response = wrapped_callback(request, *callback_args, **callback_kwargs)
  File "D:\ProgramData\Anaconda3\envs\website\lib\site-packages\django\views\decorators\csrf.py", line 54, in wrapped_view
    return view_func(*args, **kwargs)
  File "D:\ProgramData\Anaconda3\envs\website\lib\site-packages\rest_framework\viewsets.py", line 125, in view
    return self.dispatch(request, *args, **kwargs)
  File "D:\ProgramData\Anaconda3\envs\website\lib\site-packages\rest_framework\views.py", line 509, in dispatch
    response = self.handle_exception(exc)
  File "D:\ProgramData\Anaconda3\envs\website\lib\site-packages\rest_framework\views.py", line 469, in handle_exception
    self.raise_uncaught_exception(exc)
  File "D:\ProgramData\Anaconda3\envs\website\lib\site-packages\rest_framework\views.py", line 480, in raise_uncaught_exception
    raise exc
  File "D:\ProgramData\Anaconda3\envs\website\lib\site-packages\rest_framework\views.py", line 506, in dispatch
    response = handler(request, *args, **kwargs)
  File "D:\Website\minzufs.cn\minzufs\identify\viewsets.py", line 75, in change_nation
    real_ip = request.META['HTTP_X_FORWARDED_FOR']
KeyError: 'HTTP_X_FORWARDED_FOR'
[2022-01-12 16:12:02,818][Thread-16:2828][task_id:django.server][basehttp.py:154][ERROR]["GET /api/images/54/change-nation/?name=1231 HTTP/1.1" 500 19265]
[2022-01-12 16:12:08,264][Thread-16:2828][task_id:django.request][log.py:228][ERROR][Internal Server Error: /api/images/54/change-nation/]
Traceback (most recent call last):
  File "D:\ProgramData\Anaconda3\envs\website\lib\site-packages\django\core\handlers\exception.py", line 34, in inner
    response = get_response(request)
  File "D:\ProgramData\Anaconda3\envs\website\lib\site-packages\django\core\handlers\base.py", line 115, in _get_response
    response = self.process_exception_by_middleware(e, request)
  File "D:\ProgramData\Anaconda3\envs\website\lib\site-packages\django\core\handlers\base.py", line 113, in _get_response
    response = wrapped_callback(request, *callback_args, **callback_kwargs)
  File "D:\ProgramData\Anaconda3\envs\website\lib\site-packages\django\views\decorators\csrf.py", line 54, in wrapped_view
    return view_func(*args, **kwargs)
  File "D:\ProgramData\Anaconda3\envs\website\lib\site-packages\rest_framework\viewsets.py", line 125, in view
    return self.dispatch(request, *args, **kwargs)
  File "D:\ProgramData\Anaconda3\envs\website\lib\site-packages\rest_framework\views.py", line 509, in dispatch
    response = self.handle_exception(exc)
  File "D:\ProgramData\Anaconda3\envs\website\lib\site-packages\rest_framework\views.py", line 469, in handle_exception
    self.raise_uncaught_exception(exc)
  File "D:\ProgramData\Anaconda3\envs\website\lib\site-packages\rest_framework\views.py", line 480, in raise_uncaught_exception
    raise exc
  File "D:\ProgramData\Anaconda3\envs\website\lib\site-packages\rest_framework\views.py", line 506, in dispatch
    response = handler(request, *args, **kwargs)
  File "D:\Website\minzufs.cn\minzufs\identify\viewsets.py", line 75, in change_nation
    real_ip = request.META['HTTP_X_FORWARDED_FOR']
KeyError: 'HTTP_X_FORWARDED_FOR'
[2022-01-12 16:12:08,266][Thread-16:2828][task_id:django.server][basehttp.py:154][ERROR]["GET /api/images/54/change-nation/?name=1231 HTTP/1.1" 500 19265]
[2022-01-12 16:12:23,046][Thread-20:13612][task_id:django.request][log.py:228][ERROR][Internal Server Error: /api/images/54/change-nation/]
Traceback (most recent call last):
  File "D:\ProgramData\Anaconda3\envs\website\lib\site-packages\django\core\handlers\exception.py", line 34, in inner
    response = get_response(request)
  File "D:\ProgramData\Anaconda3\envs\website\lib\site-packages\django\core\handlers\base.py", line 115, in _get_response
    response = self.process_exception_by_middleware(e, request)
  File "D:\ProgramData\Anaconda3\envs\website\lib\site-packages\django\core\handlers\base.py", line 113, in _get_response
    response = wrapped_callback(request, *callback_args, **callback_kwargs)
  File "D:\ProgramData\Anaconda3\envs\website\lib\site-packages\django\views\decorators\csrf.py", line 54, in wrapped_view
    return view_func(*args, **kwargs)
  File "D:\ProgramData\Anaconda3\envs\website\lib\site-packages\rest_framework\viewsets.py", line 125, in view
    return self.dispatch(request, *args, **kwargs)
  File "D:\ProgramData\Anaconda3\envs\website\lib\site-packages\rest_framework\views.py", line 509, in dispatch
    response = self.handle_exception(exc)
  File "D:\ProgramData\Anaconda3\envs\website\lib\site-packages\rest_framework\views.py", line 469, in handle_exception
    self.raise_uncaught_exception(exc)
  File "D:\ProgramData\Anaconda3\envs\website\lib\site-packages\rest_framework\views.py", line 480, in raise_uncaught_exception
    raise exc
  File "D:\ProgramData\Anaconda3\envs\website\lib\site-packages\rest_framework\views.py", line 506, in dispatch
    response = handler(request, *args, **kwargs)
  File "D:\Website\minzufs.cn\minzufs\identify\viewsets.py", line 75, in change_nation
    real_ip = request.META['HTTP_X_FORWARDED_FOR']
KeyError: 'HTTP_X_FORWARDED_FOR'
[2022-01-12 16:12:23,048][Thread-20:13612][task_id:django.server][basehttp.py:154][ERROR]["GET /api/images/54/change-nation/?name=1231 HTTP/1.1" 500 19265]
[2022-01-12 16:13:15,988][Thread-20:13612][task_id:django.request][log.py:228][ERROR][Internal Server Error: /api/images/55/change-nation/]
Traceback (most recent call last):
  File "D:\ProgramData\Anaconda3\envs\website\lib\site-packages\django\core\handlers\exception.py", line 34, in inner
    response = get_response(request)
  File "D:\ProgramData\Anaconda3\envs\website\lib\site-packages\django\core\handlers\base.py", line 115, in _get_response
    response = self.process_exception_by_middleware(e, request)
  File "D:\ProgramData\Anaconda3\envs\website\lib\site-packages\django\core\handlers\base.py", line 113, in _get_response
    response = wrapped_callback(request, *callback_args, **callback_kwargs)
  File "D:\ProgramData\Anaconda3\envs\website\lib\site-packages\django\views\decorators\csrf.py", line 54, in wrapped_view
    return view_func(*args, **kwargs)
  File "D:\ProgramData\Anaconda3\envs\website\lib\site-packages\rest_framework\viewsets.py", line 125, in view
    return self.dispatch(request, *args, **kwargs)
  File "D:\ProgramData\Anaconda3\envs\website\lib\site-packages\rest_framework\views.py", line 509, in dispatch
    response = self.handle_exception(exc)
  File "D:\ProgramData\Anaconda3\envs\website\lib\site-packages\rest_framework\views.py", line 469, in handle_exception
    self.raise_uncaught_exception(exc)
  File "D:\ProgramData\Anaconda3\envs\website\lib\site-packages\rest_framework\views.py", line 480, in raise_uncaught_exception
    raise exc
  File "D:\ProgramData\Anaconda3\envs\website\lib\site-packages\rest_framework\views.py", line 506, in dispatch
    response = handler(request, *args, **kwargs)
  File "D:\Website\minzufs.cn\minzufs\identify\viewsets.py", line 75, in change_nation
    real_ip = request.META['HTTP_X_FORWARDED_FOR']
KeyError: 'HTTP_X_FORWARDED_FOR'
[2022-01-12 16:13:15,989][Thread-20:13612][task_id:django.server][basehttp.py:154][ERROR]["GET /api/images/55/change-nation/?name=021 HTTP/1.1" 500 19262]
[2022-01-12 16:13:23,851][Thread-20:13612][task_id:django.request][log.py:228][ERROR][Internal Server Error: /api/images/55/change-nation/]
Traceback (most recent call last):
  File "D:\ProgramData\Anaconda3\envs\website\lib\site-packages\django\core\handlers\exception.py", line 34, in inner
    response = get_response(request)
  File "D:\ProgramData\Anaconda3\envs\website\lib\site-packages\django\core\handlers\base.py", line 115, in _get_response
    response = self.process_exception_by_middleware(e, request)
  File "D:\ProgramData\Anaconda3\envs\website\lib\site-packages\django\core\handlers\base.py", line 113, in _get_response
    response = wrapped_callback(request, *callback_args, **callback_kwargs)
  File "D:\ProgramData\Anaconda3\envs\website\lib\site-packages\django\views\decorators\csrf.py", line 54, in wrapped_view
    return view_func(*args, **kwargs)
  File "D:\ProgramData\Anaconda3\envs\website\lib\site-packages\rest_framework\viewsets.py", line 125, in view
    return self.dispatch(request, *args, **kwargs)
  File "D:\ProgramData\Anaconda3\envs\website\lib\site-packages\rest_framework\views.py", line 509, in dispatch
    response = self.handle_exception(exc)
  File "D:\ProgramData\Anaconda3\envs\website\lib\site-packages\rest_framework\views.py", line 469, in handle_exception
    self.raise_uncaught_exception(exc)
  File "D:\ProgramData\Anaconda3\envs\website\lib\site-packages\rest_framework\views.py", line 480, in raise_uncaught_exception
    raise exc
  File "D:\ProgramData\Anaconda3\envs\website\lib\site-packages\rest_framework\views.py", line 506, in dispatch
    response = handler(request, *args, **kwargs)
  File "D:\Website\minzufs.cn\minzufs\identify\viewsets.py", line 75, in change_nation
    real_ip = request.META['HTTP_X_FORWARDED_FOR']
KeyError: 'HTTP_X_FORWARDED_FOR'
[2022-01-12 16:13:23,852][Thread-20:13612][task_id:django.server][basehttp.py:154][ERROR]["GET /api/images/55/change-nation/?name=021 HTTP/1.1" 500 19262]
[2022-01-12 16:13:24,069][Thread-20:13612][task_id:django.request][log.py:228][ERROR][Internal Server Error: /api/images/55/change-nation/]
Traceback (most recent call last):
  File "D:\ProgramData\Anaconda3\envs\website\lib\site-packages\django\core\handlers\exception.py", line 34, in inner
    response = get_response(request)
  File "D:\ProgramData\Anaconda3\envs\website\lib\site-packages\django\core\handlers\base.py", line 115, in _get_response
    response = self.process_exception_by_middleware(e, request)
  File "D:\ProgramData\Anaconda3\envs\website\lib\site-packages\django\core\handlers\base.py", line 113, in _get_response
    response = wrapped_callback(request, *callback_args, **callback_kwargs)
  File "D:\ProgramData\Anaconda3\envs\website\lib\site-packages\django\views\decorators\csrf.py", line 54, in wrapped_view
    return view_func(*args, **kwargs)
  File "D:\ProgramData\Anaconda3\envs\website\lib\site-packages\rest_framework\viewsets.py", line 125, in view
    return self.dispatch(request, *args, **kwargs)
  File "D:\ProgramData\Anaconda3\envs\website\lib\site-packages\rest_framework\views.py", line 509, in dispatch
    response = self.handle_exception(exc)
  File "D:\ProgramData\Anaconda3\envs\website\lib\site-packages\rest_framework\views.py", line 469, in handle_exception
    self.raise_uncaught_exception(exc)
  File "D:\ProgramData\Anaconda3\envs\website\lib\site-packages\rest_framework\views.py", line 480, in raise_uncaught_exception
    raise exc
  File "D:\ProgramData\Anaconda3\envs\website\lib\site-packages\rest_framework\views.py", line 506, in dispatch
    response = handler(request, *args, **kwargs)
  File "D:\Website\minzufs.cn\minzufs\identify\viewsets.py", line 75, in change_nation
    real_ip = request.META['HTTP_X_FORWARDED_FOR']
KeyError: 'HTTP_X_FORWARDED_FOR'
[2022-01-12 16:13:24,070][Thread-20:13612][task_id:django.server][basehttp.py:154][ERROR]["GET /api/images/55/change-nation/?name=021 HTTP/1.1" 500 19262]
[2022-01-12 16:13:25,357][Thread-20:13612][task_id:django.request][log.py:228][ERROR][Internal Server Error: /api/images/55/change-nation/]
Traceback (most recent call last):
  File "D:\ProgramData\Anaconda3\envs\website\lib\site-packages\django\core\handlers\exception.py", line 34, in inner
    response = get_response(request)
  File "D:\ProgramData\Anaconda3\envs\website\lib\site-packages\django\core\handlers\base.py", line 115, in _get_response
    response = self.process_exception_by_middleware(e, request)
  File "D:\ProgramData\Anaconda3\envs\website\lib\site-packages\django\core\handlers\base.py", line 113, in _get_response
    response = wrapped_callback(request, *callback_args, **callback_kwargs)
  File "D:\ProgramData\Anaconda3\envs\website\lib\site-packages\django\views\decorators\csrf.py", line 54, in wrapped_view
    return view_func(*args, **kwargs)
  File "D:\ProgramData\Anaconda3\envs\website\lib\site-packages\rest_framework\viewsets.py", line 125, in view
    return self.dispatch(request, *args, **kwargs)
  File "D:\ProgramData\Anaconda3\envs\website\lib\site-packages\rest_framework\views.py", line 509, in dispatch
    response = self.handle_exception(exc)
  File "D:\ProgramData\Anaconda3\envs\website\lib\site-packages\rest_framework\views.py", line 469, in handle_exception
    self.raise_uncaught_exception(exc)
  File "D:\ProgramData\Anaconda3\envs\website\lib\site-packages\rest_framework\views.py", line 480, in raise_uncaught_exception
    raise exc
  File "D:\ProgramData\Anaconda3\envs\website\lib\site-packages\rest_framework\views.py", line 506, in dispatch
    response = handler(request, *args, **kwargs)
  File "D:\Website\minzufs.cn\minzufs\identify\viewsets.py", line 75, in change_nation
    real_ip = request.META['HTTP_X_FORWARDED_FOR']
KeyError: 'HTTP_X_FORWARDED_FOR'
[2022-01-12 16:13:25,359][Thread-20:13612][task_id:django.server][basehttp.py:154][ERROR]["GET /api/images/55/change-nation/?name=021 HTTP/1.1" 500 19262]
[2022-01-12 16:13:25,806][Thread-20:13612][task_id:django.request][log.py:228][ERROR][Internal Server Error: /api/images/55/change-nation/]
Traceback (most recent call last):
  File "D:\ProgramData\Anaconda3\envs\website\lib\site-packages\django\core\handlers\exception.py", line 34, in inner
    response = get_response(request)
  File "D:\ProgramData\Anaconda3\envs\website\lib\site-packages\django\core\handlers\base.py", line 115, in _get_response
    response = self.process_exception_by_middleware(e, request)
  File "D:\ProgramData\Anaconda3\envs\website\lib\site-packages\django\core\handlers\base.py", line 113, in _get_response
    response = wrapped_callback(request, *callback_args, **callback_kwargs)
  File "D:\ProgramData\Anaconda3\envs\website\lib\site-packages\django\views\decorators\csrf.py", line 54, in wrapped_view
    return view_func(*args, **kwargs)
  File "D:\ProgramData\Anaconda3\envs\website\lib\site-packages\rest_framework\viewsets.py", line 125, in view
    return self.dispatch(request, *args, **kwargs)
  File "D:\ProgramData\Anaconda3\envs\website\lib\site-packages\rest_framework\views.py", line 509, in dispatch
    response = self.handle_exception(exc)
  File "D:\ProgramData\Anaconda3\envs\website\lib\site-packages\rest_framework\views.py", line 469, in handle_exception
    self.raise_uncaught_exception(exc)
  File "D:\ProgramData\Anaconda3\envs\website\lib\site-packages\rest_framework\views.py", line 480, in raise_uncaught_exception
    raise exc
  File "D:\ProgramData\Anaconda3\envs\website\lib\site-packages\rest_framework\views.py", line 506, in dispatch
    response = handler(request, *args, **kwargs)
  File "D:\Website\minzufs.cn\minzufs\identify\viewsets.py", line 75, in change_nation
    real_ip = request.META['HTTP_X_FORWARDED_FOR']
KeyError: 'HTTP_X_FORWARDED_FOR'
[2022-01-12 16:13:25,808][Thread-20:13612][task_id:django.server][basehttp.py:154][ERROR]["GET /api/images/55/change-nation/?name=021 HTTP/1.1" 500 19262]
[2022-01-12 16:13:26,371][Thread-20:13612][task_id:django.request][log.py:228][ERROR][Internal Server Error: /api/images/55/change-nation/]
Traceback (most recent call last):
  File "D:\ProgramData\Anaconda3\envs\website\lib\site-packages\django\core\handlers\exception.py", line 34, in inner
    response = get_response(request)
  File "D:\ProgramData\Anaconda3\envs\website\lib\site-packages\django\core\handlers\base.py", line 115, in _get_response
    response = self.process_exception_by_middleware(e, request)
  File "D:\ProgramData\Anaconda3\envs\website\lib\site-packages\django\core\handlers\base.py", line 113, in _get_response
    response = wrapped_callback(request, *callback_args, **callback_kwargs)
  File "D:\ProgramData\Anaconda3\envs\website\lib\site-packages\django\views\decorators\csrf.py", line 54, in wrapped_view
    return view_func(*args, **kwargs)
  File "D:\ProgramData\Anaconda3\envs\website\lib\site-packages\rest_framework\viewsets.py", line 125, in view
    return self.dispatch(request, *args, **kwargs)
  File "D:\ProgramData\Anaconda3\envs\website\lib\site-packages\rest_framework\views.py", line 509, in dispatch
    response = self.handle_exception(exc)
  File "D:\ProgramData\Anaconda3\envs\website\lib\site-packages\rest_framework\views.py", line 469, in handle_exception
    self.raise_uncaught_exception(exc)
  File "D:\ProgramData\Anaconda3\envs\website\lib\site-packages\rest_framework\views.py", line 480, in raise_uncaught_exception
    raise exc
  File "D:\ProgramData\Anaconda3\envs\website\lib\site-packages\rest_framework\views.py", line 506, in dispatch
    response = handler(request, *args, **kwargs)
  File "D:\Website\minzufs.cn\minzufs\identify\viewsets.py", line 75, in change_nation
    real_ip = request.META['HTTP_X_FORWARDED_FOR']
KeyError: 'HTTP_X_FORWARDED_FOR'
[2022-01-12 16:13:26,372][Thread-20:13612][task_id:django.server][basehttp.py:154][ERROR]["GET /api/images/55/change-nation/?name=021 HTTP/1.1" 500 19262]
[2022-01-12 16:13:26,799][Thread-20:13612][task_id:django.request][log.py:228][ERROR][Internal Server Error: /api/images/55/change-nation/]
Traceback (most recent call last):
  File "D:\ProgramData\Anaconda3\envs\website\lib\site-packages\django\core\handlers\exception.py", line 34, in inner
    response = get_response(request)
  File "D:\ProgramData\Anaconda3\envs\website\lib\site-packages\django\core\handlers\base.py", line 115, in _get_response
    response = self.process_exception_by_middleware(e, request)
  File "D:\ProgramData\Anaconda3\envs\website\lib\site-packages\django\core\handlers\base.py", line 113, in _get_response
    response = wrapped_callback(request, *callback_args, **callback_kwargs)
  File "D:\ProgramData\Anaconda3\envs\website\lib\site-packages\django\views\decorators\csrf.py", line 54, in wrapped_view
    return view_func(*args, **kwargs)
  File "D:\ProgramData\Anaconda3\envs\website\lib\site-packages\rest_framework\viewsets.py", line 125, in view
    return self.dispatch(request, *args, **kwargs)
  File "D:\ProgramData\Anaconda3\envs\website\lib\site-packages\rest_framework\views.py", line 509, in dispatch
    response = self.handle_exception(exc)
  File "D:\ProgramData\Anaconda3\envs\website\lib\site-packages\rest_framework\views.py", line 469, in handle_exception
    self.raise_uncaught_exception(exc)
  File "D:\ProgramData\Anaconda3\envs\website\lib\site-packages\rest_framework\views.py", line 480, in raise_uncaught_exception
    raise exc
  File "D:\ProgramData\Anaconda3\envs\website\lib\site-packages\rest_framework\views.py", line 506, in dispatch
    response = handler(request, *args, **kwargs)
  File "D:\Website\minzufs.cn\minzufs\identify\viewsets.py", line 75, in change_nation
    real_ip = request.META['HTTP_X_FORWARDED_FOR']
KeyError: 'HTTP_X_FORWARDED_FOR'
[2022-01-12 16:13:26,800][Thread-20:13612][task_id:django.server][basehttp.py:154][ERROR]["GET /api/images/55/change-nation/?name=021 HTTP/1.1" 500 19262]
[2022-01-12 16:13:27,046][Thread-20:13612][task_id:django.request][log.py:228][ERROR][Internal Server Error: /api/images/55/change-nation/]
Traceback (most recent call last):
  File "D:\ProgramData\Anaconda3\envs\website\lib\site-packages\django\core\handlers\exception.py", line 34, in inner
    response = get_response(request)
  File "D:\ProgramData\Anaconda3\envs\website\lib\site-packages\django\core\handlers\base.py", line 115, in _get_response
    response = self.process_exception_by_middleware(e, request)
  File "D:\ProgramData\Anaconda3\envs\website\lib\site-packages\django\core\handlers\base.py", line 113, in _get_response
    response = wrapped_callback(request, *callback_args, **callback_kwargs)
  File "D:\ProgramData\Anaconda3\envs\website\lib\site-packages\django\views\decorators\csrf.py", line 54, in wrapped_view
    return view_func(*args, **kwargs)
  File "D:\ProgramData\Anaconda3\envs\website\lib\site-packages\rest_framework\viewsets.py", line 125, in view
    return self.dispatch(request, *args, **kwargs)
  File "D:\ProgramData\Anaconda3\envs\website\lib\site-packages\rest_framework\views.py", line 509, in dispatch
    response = self.handle_exception(exc)
  File "D:\ProgramData\Anaconda3\envs\website\lib\site-packages\rest_framework\views.py", line 469, in handle_exception
    self.raise_uncaught_exception(exc)
  File "D:\ProgramData\Anaconda3\envs\website\lib\site-packages\rest_framework\views.py", line 480, in raise_uncaught_exception
    raise exc
  File "D:\ProgramData\Anaconda3\envs\website\lib\site-packages\rest_framework\views.py", line 506, in dispatch
    response = handler(request, *args, **kwargs)
  File "D:\Website\minzufs.cn\minzufs\identify\viewsets.py", line 75, in change_nation
    real_ip = request.META['HTTP_X_FORWARDED_FOR']
KeyError: 'HTTP_X_FORWARDED_FOR'
[2022-01-12 16:13:27,048][Thread-20:13612][task_id:django.server][basehttp.py:154][ERROR]["GET /api/images/55/change-nation/?name=021 HTTP/1.1" 500 19262]
[2022-01-12 16:13:27,477][Thread-20:13612][task_id:django.request][log.py:228][ERROR][Internal Server Error: /api/images/55/change-nation/]
Traceback (most recent call last):
  File "D:\ProgramData\Anaconda3\envs\website\lib\site-packages\django\core\handlers\exception.py", line 34, in inner
    response = get_response(request)
  File "D:\ProgramData\Anaconda3\envs\website\lib\site-packages\django\core\handlers\base.py", line 115, in _get_response
    response = self.process_exception_by_middleware(e, request)
  File "D:\ProgramData\Anaconda3\envs\website\lib\site-packages\django\core\handlers\base.py", line 113, in _get_response
    response = wrapped_callback(request, *callback_args, **callback_kwargs)
  File "D:\ProgramData\Anaconda3\envs\website\lib\site-packages\django\views\decorators\csrf.py", line 54, in wrapped_view
    return view_func(*args, **kwargs)
  File "D:\ProgramData\Anaconda3\envs\website\lib\site-packages\rest_framework\viewsets.py", line 125, in view
    return self.dispatch(request, *args, **kwargs)
  File "D:\ProgramData\Anaconda3\envs\website\lib\site-packages\rest_framework\views.py", line 509, in dispatch
    response = self.handle_exception(exc)
  File "D:\ProgramData\Anaconda3\envs\website\lib\site-packages\rest_framework\views.py", line 469, in handle_exception
    self.raise_uncaught_exception(exc)
  File "D:\ProgramData\Anaconda3\envs\website\lib\site-packages\rest_framework\views.py", line 480, in raise_uncaught_exception
    raise exc
  File "D:\ProgramData\Anaconda3\envs\website\lib\site-packages\rest_framework\views.py", line 506, in dispatch
    response = handler(request, *args, **kwargs)
  File "D:\Website\minzufs.cn\minzufs\identify\viewsets.py", line 75, in change_nation
    real_ip = request.META['HTTP_X_FORWARDED_FOR']
KeyError: 'HTTP_X_FORWARDED_FOR'
[2022-01-12 16:13:27,687][Thread-20:13612][task_id:django.server][basehttp.py:154][ERROR]["GET /api/images/55/change-nation/?name=021 HTTP/1.1" 500 19262]
[2022-01-12 16:13:27,703][Thread-21:10932][task_id:django.request][log.py:228][ERROR][Internal Server Error: /api/images/55/change-nation/]
Traceback (most recent call last):
  File "D:\ProgramData\Anaconda3\envs\website\lib\site-packages\django\core\handlers\exception.py", line 34, in inner
    response = get_response(request)
  File "D:\ProgramData\Anaconda3\envs\website\lib\site-packages\django\core\handlers\base.py", line 115, in _get_response
    response = self.process_exception_by_middleware(e, request)
  File "D:\ProgramData\Anaconda3\envs\website\lib\site-packages\django\core\handlers\base.py", line 113, in _get_response
    response = wrapped_callback(request, *callback_args, **callback_kwargs)
  File "D:\ProgramData\Anaconda3\envs\website\lib\site-packages\django\views\decorators\csrf.py", line 54, in wrapped_view
    return view_func(*args, **kwargs)
  File "D:\ProgramData\Anaconda3\envs\website\lib\site-packages\rest_framework\viewsets.py", line 125, in view
    return self.dispatch(request, *args, **kwargs)
  File "D:\ProgramData\Anaconda3\envs\website\lib\site-packages\rest_framework\views.py", line 509, in dispatch
    response = self.handle_exception(exc)
  File "D:\ProgramData\Anaconda3\envs\website\lib\site-packages\rest_framework\views.py", line 469, in handle_exception
    self.raise_uncaught_exception(exc)
  File "D:\ProgramData\Anaconda3\envs\website\lib\site-packages\rest_framework\views.py", line 480, in raise_uncaught_exception
    raise exc
  File "D:\ProgramData\Anaconda3\envs\website\lib\site-packages\rest_framework\views.py", line 506, in dispatch
    response = handler(request, *args, **kwargs)
  File "D:\Website\minzufs.cn\minzufs\identify\viewsets.py", line 75, in change_nation
    real_ip = request.META['HTTP_X_FORWARDED_FOR']
KeyError: 'HTTP_X_FORWARDED_FOR'
[2022-01-12 16:13:27,705][Thread-21:10932][task_id:django.server][basehttp.py:154][ERROR]["GET /api/images/55/change-nation/?name=021 HTTP/1.1" 500 19262]
[2022-01-12 16:13:28,194][Thread-21:10932][task_id:django.request][log.py:228][ERROR][Internal Server Error: /api/images/55/change-nation/]
Traceback (most recent call last):
  File "D:\ProgramData\Anaconda3\envs\website\lib\site-packages\django\core\handlers\exception.py", line 34, in inner
    response = get_response(request)
  File "D:\ProgramData\Anaconda3\envs\website\lib\site-packages\django\core\handlers\base.py", line 115, in _get_response
    response = self.process_exception_by_middleware(e, request)
  File "D:\ProgramData\Anaconda3\envs\website\lib\site-packages\django\core\handlers\base.py", line 113, in _get_response
    response = wrapped_callback(request, *callback_args, **callback_kwargs)
  File "D:\ProgramData\Anaconda3\envs\website\lib\site-packages\django\views\decorators\csrf.py", line 54, in wrapped_view
    return view_func(*args, **kwargs)
  File "D:\ProgramData\Anaconda3\envs\website\lib\site-packages\rest_framework\viewsets.py", line 125, in view
    return self.dispatch(request, *args, **kwargs)
  File "D:\ProgramData\Anaconda3\envs\website\lib\site-packages\rest_framework\views.py", line 509, in dispatch
    response = self.handle_exception(exc)
  File "D:\ProgramData\Anaconda3\envs\website\lib\site-packages\rest_framework\views.py", line 469, in handle_exception
    self.raise_uncaught_exception(exc)
  File "D:\ProgramData\Anaconda3\envs\website\lib\site-packages\rest_framework\views.py", line 480, in raise_uncaught_exception
    raise exc
  File "D:\ProgramData\Anaconda3\envs\website\lib\site-packages\rest_framework\views.py", line 506, in dispatch
    response = handler(request, *args, **kwargs)
  File "D:\Website\minzufs.cn\minzufs\identify\viewsets.py", line 75, in change_nation
    real_ip = request.META['HTTP_X_FORWARDED_FOR']
KeyError: 'HTTP_X_FORWARDED_FOR'
[2022-01-12 16:13:28,195][Thread-21:10932][task_id:django.server][basehttp.py:154][ERROR]["GET /api/images/55/change-nation/?name=021 HTTP/1.1" 500 19262]
[2022-01-12 16:15:05,272][Thread-1:8284][task_id:django.request][log.py:228][ERROR][Internal Server Error: /api/images/55/change-nation/]
Traceback (most recent call last):
  File "D:\ProgramData\Anaconda3\envs\website\lib\site-packages\django\core\handlers\exception.py", line 34, in inner
    response = get_response(request)
  File "D:\ProgramData\Anaconda3\envs\website\lib\site-packages\django\core\handlers\base.py", line 115, in _get_response
    response = self.process_exception_by_middleware(e, request)
  File "D:\ProgramData\Anaconda3\envs\website\lib\site-packages\django\core\handlers\base.py", line 113, in _get_response
    response = wrapped_callback(request, *callback_args, **callback_kwargs)
  File "D:\ProgramData\Anaconda3\envs\website\lib\site-packages\django\views\decorators\csrf.py", line 54, in wrapped_view
    return view_func(*args, **kwargs)
  File "D:\ProgramData\Anaconda3\envs\website\lib\site-packages\rest_framework\viewsets.py", line 125, in view
    return self.dispatch(request, *args, **kwargs)
  File "D:\ProgramData\Anaconda3\envs\website\lib\site-packages\rest_framework\views.py", line 509, in dispatch
    response = self.handle_exception(exc)
  File "D:\ProgramData\Anaconda3\envs\website\lib\site-packages\rest_framework\views.py", line 469, in handle_exception
    self.raise_uncaught_exception(exc)
  File "D:\ProgramData\Anaconda3\envs\website\lib\site-packages\rest_framework\views.py", line 480, in raise_uncaught_exception
    raise exc
  File "D:\ProgramData\Anaconda3\envs\website\lib\site-packages\rest_framework\views.py", line 506, in dispatch
    response = handler(request, *args, **kwargs)
  File "D:\Website\minzufs.cn\minzufs\identify\viewsets.py", line 78, in change_nation
    print(request.META['HTTP_X_FORWARDED_FOR'])
KeyError: 'HTTP_X_FORWARDED_FOR'
[2022-01-12 16:15:05,274][Thread-1:8284][task_id:django.server][basehttp.py:154][ERROR]["GET /api/images/55/change-nation/?name=sada HTTP/1.1" 500 19262]
[2022-01-12 16:15:05,605][Thread-1:8284][task_id:django.request][log.py:228][ERROR][Internal Server Error: /api/images/55/change-nation/]
Traceback (most recent call last):
  File "D:\ProgramData\Anaconda3\envs\website\lib\site-packages\django\core\handlers\exception.py", line 34, in inner
    response = get_response(request)
  File "D:\ProgramData\Anaconda3\envs\website\lib\site-packages\django\core\handlers\base.py", line 115, in _get_response
    response = self.process_exception_by_middleware(e, request)
  File "D:\ProgramData\Anaconda3\envs\website\lib\site-packages\django\core\handlers\base.py", line 113, in _get_response
    response = wrapped_callback(request, *callback_args, **callback_kwargs)
  File "D:\ProgramData\Anaconda3\envs\website\lib\site-packages\django\views\decorators\csrf.py", line 54, in wrapped_view
    return view_func(*args, **kwargs)
  File "D:\ProgramData\Anaconda3\envs\website\lib\site-packages\rest_framework\viewsets.py", line 125, in view
    return self.dispatch(request, *args, **kwargs)
  File "D:\ProgramData\Anaconda3\envs\website\lib\site-packages\rest_framework\views.py", line 509, in dispatch
    response = self.handle_exception(exc)
  File "D:\ProgramData\Anaconda3\envs\website\lib\site-packages\rest_framework\views.py", line 469, in handle_exception
    self.raise_uncaught_exception(exc)
  File "D:\ProgramData\Anaconda3\envs\website\lib\site-packages\rest_framework\views.py", line 480, in raise_uncaught_exception
    raise exc
  File "D:\ProgramData\Anaconda3\envs\website\lib\site-packages\rest_framework\views.py", line 506, in dispatch
    response = handler(request, *args, **kwargs)
  File "D:\Website\minzufs.cn\minzufs\identify\viewsets.py", line 78, in change_nation
    print(request.META['HTTP_X_FORWARDED_FOR'])
KeyError: 'HTTP_X_FORWARDED_FOR'
[2022-01-12 16:15:05,607][Thread-1:8284][task_id:django.server][basehttp.py:154][ERROR]["GET /api/images/55/change-nation/?name=sada HTTP/1.1" 500 19262]
[2022-01-12 16:38:42,998][Thread-1:15456][task_id:django.request][log.py:228][ERROR][Internal Server Error: /api/images/]
Traceback (most recent call last):
  File "D:\ProgramData\Anaconda3\envs\website\lib\site-packages\django\core\handlers\exception.py", line 34, in inner
    response = get_response(request)
  File "D:\ProgramData\Anaconda3\envs\website\lib\site-packages\django\core\handlers\base.py", line 115, in _get_response
    response = self.process_exception_by_middleware(e, request)
  File "D:\ProgramData\Anaconda3\envs\website\lib\site-packages\django\core\handlers\base.py", line 113, in _get_response
    response = wrapped_callback(request, *callback_args, **callback_kwargs)
  File "D:\ProgramData\Anaconda3\envs\website\lib\site-packages\django\views\decorators\csrf.py", line 54, in wrapped_view
    return view_func(*args, **kwargs)
  File "D:\ProgramData\Anaconda3\envs\website\lib\site-packages\rest_framework\viewsets.py", line 125, in view
    return self.dispatch(request, *args, **kwargs)
  File "D:\ProgramData\Anaconda3\envs\website\lib\site-packages\rest_framework\views.py", line 509, in dispatch
    response = self.handle_exception(exc)
  File "D:\ProgramData\Anaconda3\envs\website\lib\site-packages\rest_framework\views.py", line 469, in handle_exception
    self.raise_uncaught_exception(exc)
  File "D:\ProgramData\Anaconda3\envs\website\lib\site-packages\rest_framework\views.py", line 480, in raise_uncaught_exception
    raise exc
  File "D:\ProgramData\Anaconda3\envs\website\lib\site-packages\rest_framework\views.py", line 506, in dispatch
    response = handler(request, *args, **kwargs)
  File "D:\ProgramData\Anaconda3\envs\website\lib\site-packages\rest_framework\mixins.py", line 19, in create
    self.perform_create(serializer)
  File "D:\Website\minzufs.cn\minzufs\identify\viewsets.py", line 56, in perform_create
    print(self.request.data.upload_images)
AttributeError: 'QueryDict' object has no attribute 'upload_images'
[2022-01-12 16:38:43,000][Thread-1:15456][task_id:django.server][basehttp.py:154][ERROR]["POST /api/images/ HTTP/1.1" 500 19317]
[2022-01-12 16:39:42,994][Thread-1:15704][task_id:django.request][log.py:228][ERROR][Internal Server Error: /api/images/]
Traceback (most recent call last):
  File "D:\ProgramData\Anaconda3\envs\website\lib\site-packages\django\core\handlers\exception.py", line 34, in inner
    response = get_response(request)
  File "D:\ProgramData\Anaconda3\envs\website\lib\site-packages\django\core\handlers\base.py", line 115, in _get_response
    response = self.process_exception_by_middleware(e, request)
  File "D:\ProgramData\Anaconda3\envs\website\lib\site-packages\django\core\handlers\base.py", line 113, in _get_response
    response = wrapped_callback(request, *callback_args, **callback_kwargs)
  File "D:\ProgramData\Anaconda3\envs\website\lib\site-packages\django\views\decorators\csrf.py", line 54, in wrapped_view
    return view_func(*args, **kwargs)
  File "D:\ProgramData\Anaconda3\envs\website\lib\site-packages\rest_framework\viewsets.py", line 125, in view
    return self.dispatch(request, *args, **kwargs)
  File "D:\ProgramData\Anaconda3\envs\website\lib\site-packages\rest_framework\views.py", line 509, in dispatch
    response = self.handle_exception(exc)
  File "D:\ProgramData\Anaconda3\envs\website\lib\site-packages\rest_framework\views.py", line 469, in handle_exception
    self.raise_uncaught_exception(exc)
  File "D:\ProgramData\Anaconda3\envs\website\lib\site-packages\rest_framework\views.py", line 480, in raise_uncaught_exception
    raise exc
  File "D:\ProgramData\Anaconda3\envs\website\lib\site-packages\rest_framework\views.py", line 506, in dispatch
    response = handler(request, *args, **kwargs)
  File "D:\ProgramData\Anaconda3\envs\website\lib\site-packages\rest_framework\mixins.py", line 19, in create
    self.perform_create(serializer)
  File "D:\Website\minzufs.cn\minzufs\identify\viewsets.py", line 57, in perform_create
    print(self.request.POST.__name__)
AttributeError: 'QueryDict' object has no attribute '__name__'
[2022-01-12 16:39:42,996][Thread-1:15704][task_id:django.server][basehttp.py:154][ERROR]["POST /api/images/ HTTP/1.1" 500 19302]
[2022-01-12 16:40:36,303][Thread-1:10836][task_id:django.request][log.py:228][ERROR][Internal Server Error: /api/images/]
Traceback (most recent call last):
  File "D:\ProgramData\Anaconda3\envs\website\lib\site-packages\rest_framework\request.py", line 416, in __getattr__
    return getattr(self._request, attr)
AttributeError: 'WSGIRequest' object has no attribute 'file'

During handling of the above exception, another exception occurred:

Traceback (most recent call last):
  File "D:\ProgramData\Anaconda3\envs\website\lib\site-packages\django\core\handlers\exception.py", line 34, in inner
    response = get_response(request)
  File "D:\ProgramData\Anaconda3\envs\website\lib\site-packages\django\core\handlers\base.py", line 115, in _get_response
    response = self.process_exception_by_middleware(e, request)
  File "D:\ProgramData\Anaconda3\envs\website\lib\site-packages\django\core\handlers\base.py", line 113, in _get_response
    response = wrapped_callback(request, *callback_args, **callback_kwargs)
  File "D:\ProgramData\Anaconda3\envs\website\lib\site-packages\django\views\decorators\csrf.py", line 54, in wrapped_view
    return view_func(*args, **kwargs)
  File "D:\ProgramData\Anaconda3\envs\website\lib\site-packages\rest_framework\viewsets.py", line 125, in view
    return self.dispatch(request, *args, **kwargs)
  File "D:\ProgramData\Anaconda3\envs\website\lib\site-packages\rest_framework\views.py", line 509, in dispatch
    response = self.handle_exception(exc)
  File "D:\ProgramData\Anaconda3\envs\website\lib\site-packages\rest_framework\views.py", line 469, in handle_exception
    self.raise_uncaught_exception(exc)
  File "D:\ProgramData\Anaconda3\envs\website\lib\site-packages\rest_framework\views.py", line 480, in raise_uncaught_exception
    raise exc
  File "D:\ProgramData\Anaconda3\envs\website\lib\site-packages\rest_framework\views.py", line 506, in dispatch
    response = handler(request, *args, **kwargs)
  File "D:\ProgramData\Anaconda3\envs\website\lib\site-packages\rest_framework\mixins.py", line 19, in create
    self.perform_create(serializer)
  File "D:\Website\minzufs.cn\minzufs\identify\viewsets.py", line 56, in perform_create
    print(self.request.file)
  File "D:\ProgramData\Anaconda3\envs\website\lib\site-packages\rest_framework\request.py", line 418, in __getattr__
    return self.__getattribute__(attr)
AttributeError: 'Request' object has no attribute 'file'
[2022-01-12 16:40:36,306][Thread-1:10836][task_id:django.server][basehttp.py:154][ERROR]["POST /api/images/ HTTP/1.1" 500 19716]
[2022-01-12 16:41:57,467][Thread-1:14388][task_id:django.request][log.py:228][ERROR][Internal Server Error: /api/images/]
Traceback (most recent call last):
  File "D:\ProgramData\Anaconda3\envs\website\lib\site-packages\django\core\handlers\exception.py", line 34, in inner
    response = get_response(request)
  File "D:\ProgramData\Anaconda3\envs\website\lib\site-packages\django\core\handlers\base.py", line 115, in _get_response
    response = self.process_exception_by_middleware(e, request)
  File "D:\ProgramData\Anaconda3\envs\website\lib\site-packages\django\core\handlers\base.py", line 113, in _get_response
    response = wrapped_callback(request, *callback_args, **callback_kwargs)
  File "D:\ProgramData\Anaconda3\envs\website\lib\site-packages\django\views\decorators\csrf.py", line 54, in wrapped_view
    return view_func(*args, **kwargs)
  File "D:\ProgramData\Anaconda3\envs\website\lib\site-packages\rest_framework\viewsets.py", line 125, in view
    return self.dispatch(request, *args, **kwargs)
  File "D:\ProgramData\Anaconda3\envs\website\lib\site-packages\rest_framework\views.py", line 509, in dispatch
    response = self.handle_exception(exc)
  File "D:\ProgramData\Anaconda3\envs\website\lib\site-packages\rest_framework\views.py", line 469, in handle_exception
    self.raise_uncaught_exception(exc)
  File "D:\ProgramData\Anaconda3\envs\website\lib\site-packages\rest_framework\views.py", line 480, in raise_uncaught_exception
    raise exc
  File "D:\ProgramData\Anaconda3\envs\website\lib\site-packages\rest_framework\views.py", line 506, in dispatch
    response = handler(request, *args, **kwargs)
  File "D:\ProgramData\Anaconda3\envs\website\lib\site-packages\rest_framework\mixins.py", line 19, in create
    self.perform_create(serializer)
  File "D:\Website\minzufs.cn\minzufs\identify\viewsets.py", line 56, in perform_create
    print(self.request.FILES.__name__)
AttributeError: 'MultiValueDict' object has no attribute '__name__'
[2022-01-12 16:41:57,470][Thread-1:14388][task_id:django.server][basehttp.py:154][ERROR]["POST /api/images/ HTTP/1.1" 500 19313]
[2022-01-12 16:42:25,438][Thread-1:13432][task_id:django.request][log.py:228][ERROR][Internal Server Error: /api/images/]
Traceback (most recent call last):
  File "D:\ProgramData\Anaconda3\envs\website\lib\site-packages\django\core\handlers\exception.py", line 34, in inner
    response = get_response(request)
  File "D:\ProgramData\Anaconda3\envs\website\lib\site-packages\django\core\handlers\base.py", line 115, in _get_response
    response = self.process_exception_by_middleware(e, request)
  File "D:\ProgramData\Anaconda3\envs\website\lib\site-packages\django\core\handlers\base.py", line 113, in _get_response
    response = wrapped_callback(request, *callback_args, **callback_kwargs)
  File "D:\ProgramData\Anaconda3\envs\website\lib\site-packages\django\views\decorators\csrf.py", line 54, in wrapped_view
    return view_func(*args, **kwargs)
  File "D:\ProgramData\Anaconda3\envs\website\lib\site-packages\rest_framework\viewsets.py", line 125, in view
    return self.dispatch(request, *args, **kwargs)
  File "D:\ProgramData\Anaconda3\envs\website\lib\site-packages\rest_framework\views.py", line 509, in dispatch
    response = self.handle_exception(exc)
  File "D:\ProgramData\Anaconda3\envs\website\lib\site-packages\rest_framework\views.py", line 469, in handle_exception
    self.raise_uncaught_exception(exc)
  File "D:\ProgramData\Anaconda3\envs\website\lib\site-packages\rest_framework\views.py", line 480, in raise_uncaught_exception
    raise exc
  File "D:\ProgramData\Anaconda3\envs\website\lib\site-packages\rest_framework\views.py", line 506, in dispatch
    response = handler(request, *args, **kwargs)
  File "D:\ProgramData\Anaconda3\envs\website\lib\site-packages\rest_framework\mixins.py", line 19, in create
    self.perform_create(serializer)
  File "D:\Website\minzufs.cn\minzufs\identify\viewsets.py", line 56, in perform_create
    print(self.request.FILES.name)
AttributeError: 'MultiValueDict' object has no attribute 'name'
[2022-01-12 16:42:25,441][Thread-1:13432][task_id:django.server][basehttp.py:154][ERROR]["POST /api/images/ HTTP/1.1" 500 19301]
[2022-01-12 16:43:24,807][Thread-1:15080][task_id:django.request][log.py:228][ERROR][Internal Server Error: /api/images/]
Traceback (most recent call last):
  File "D:\ProgramData\Anaconda3\envs\website\lib\site-packages\django\utils\datastructures.py", line 78, in __getitem__
    list_ = super().__getitem__(key)
KeyError: 'filename'

During handling of the above exception, another exception occurred:

Traceback (most recent call last):
  File "D:\ProgramData\Anaconda3\envs\website\lib\site-packages\django\core\handlers\exception.py", line 34, in inner
    response = get_response(request)
  File "D:\ProgramData\Anaconda3\envs\website\lib\site-packages\django\core\handlers\base.py", line 115, in _get_response
    response = self.process_exception_by_middleware(e, request)
  File "D:\ProgramData\Anaconda3\envs\website\lib\site-packages\django\core\handlers\base.py", line 113, in _get_response
    response = wrapped_callback(request, *callback_args, **callback_kwargs)
  File "D:\ProgramData\Anaconda3\envs\website\lib\site-packages\django\views\decorators\csrf.py", line 54, in wrapped_view
    return view_func(*args, **kwargs)
  File "D:\ProgramData\Anaconda3\envs\website\lib\site-packages\rest_framework\viewsets.py", line 125, in view
    return self.dispatch(request, *args, **kwargs)
  File "D:\ProgramData\Anaconda3\envs\website\lib\site-packages\rest_framework\views.py", line 509, in dispatch
    response = self.handle_exception(exc)
  File "D:\ProgramData\Anaconda3\envs\website\lib\site-packages\rest_framework\views.py", line 469, in handle_exception
    self.raise_uncaught_exception(exc)
  File "D:\ProgramData\Anaconda3\envs\website\lib\site-packages\rest_framework\views.py", line 480, in raise_uncaught_exception
    raise exc
  File "D:\ProgramData\Anaconda3\envs\website\lib\site-packages\rest_framework\views.py", line 506, in dispatch
    response = handler(request, *args, **kwargs)
  File "D:\ProgramData\Anaconda3\envs\website\lib\site-packages\rest_framework\mixins.py", line 19, in create
    self.perform_create(serializer)
  File "D:\Website\minzufs.cn\minzufs\identify\viewsets.py", line 56, in perform_create
    print(self.request.FILES['filename'].name)
  File "D:\ProgramData\Anaconda3\envs\website\lib\site-packages\django\utils\datastructures.py", line 80, in __getitem__
    raise MultiValueDictKeyError(key)
django.utils.datastructures.MultiValueDictKeyError: 'filename'
[2022-01-12 16:43:24,810][Thread-1:15080][task_id:django.server][basehttp.py:154][ERROR]["POST /api/images/ HTTP/1.1" 500 19660]
[2022-01-12 16:45:11,460][Thread-1:2308][task_id:django.request][log.py:228][ERROR][Internal Server Error: /api/images/]
Traceback (most recent call last):
  File "D:\ProgramData\Anaconda3\envs\website\lib\site-packages\django\core\handlers\exception.py", line 34, in inner
    response = get_response(request)
  File "D:\ProgramData\Anaconda3\envs\website\lib\site-packages\django\core\handlers\base.py", line 115, in _get_response
    response = self.process_exception_by_middleware(e, request)
  File "D:\ProgramData\Anaconda3\envs\website\lib\site-packages\django\core\handlers\base.py", line 113, in _get_response
    response = wrapped_callback(request, *callback_args, **callback_kwargs)
  File "D:\ProgramData\Anaconda3\envs\website\lib\site-packages\django\views\decorators\csrf.py", line 54, in wrapped_view
    return view_func(*args, **kwargs)
  File "D:\ProgramData\Anaconda3\envs\website\lib\site-packages\rest_framework\viewsets.py", line 125, in view
    return self.dispatch(request, *args, **kwargs)
  File "D:\ProgramData\Anaconda3\envs\website\lib\site-packages\rest_framework\views.py", line 509, in dispatch
    response = self.handle_exception(exc)
  File "D:\ProgramData\Anaconda3\envs\website\lib\site-packages\rest_framework\views.py", line 469, in handle_exception
    self.raise_uncaught_exception(exc)
  File "D:\ProgramData\Anaconda3\envs\website\lib\site-packages\rest_framework\views.py", line 480, in raise_uncaught_exception
    raise exc
  File "D:\ProgramData\Anaconda3\envs\website\lib\site-packages\rest_framework\views.py", line 506, in dispatch
    response = handler(request, *args, **kwargs)
  File "D:\ProgramData\Anaconda3\envs\website\lib\site-packages\rest_framework\mixins.py", line 19, in create
    self.perform_create(serializer)
  File "D:\Website\minzufs.cn\minzufs\identify\viewsets.py", line 56, in perform_create
    print(self.request.data + ip)
TypeError: unsupported operand type(s) for +: 'QueryDict' and 'str'
[2022-01-12 16:45:11,463][Thread-1:2308][task_id:django.server][basehttp.py:154][ERROR]["POST /api/images/ HTTP/1.1" 500 19308]
[2022-01-12 16:54:33,221][Thread-1:10276][task_id:django.request][log.py:228][ERROR][Internal Server Error: /api/images/]
Traceback (most recent call last):
  File "D:\ProgramData\Anaconda3\envs\website\lib\site-packages\django\core\handlers\exception.py", line 34, in inner
    response = get_response(request)
  File "D:\ProgramData\Anaconda3\envs\website\lib\site-packages\django\core\handlers\base.py", line 115, in _get_response
    response = self.process_exception_by_middleware(e, request)
  File "D:\ProgramData\Anaconda3\envs\website\lib\site-packages\django\core\handlers\base.py", line 113, in _get_response
    response = wrapped_callback(request, *callback_args, **callback_kwargs)
  File "D:\ProgramData\Anaconda3\envs\website\lib\site-packages\django\views\decorators\csrf.py", line 54, in wrapped_view
    return view_func(*args, **kwargs)
  File "D:\ProgramData\Anaconda3\envs\website\lib\site-packages\rest_framework\viewsets.py", line 125, in view
    return self.dispatch(request, *args, **kwargs)
  File "D:\ProgramData\Anaconda3\envs\website\lib\site-packages\rest_framework\views.py", line 509, in dispatch
    response = self.handle_exception(exc)
  File "D:\ProgramData\Anaconda3\envs\website\lib\site-packages\rest_framework\views.py", line 469, in handle_exception
    self.raise_uncaught_exception(exc)
  File "D:\ProgramData\Anaconda3\envs\website\lib\site-packages\rest_framework\views.py", line 480, in raise_uncaught_exception
    raise exc
  File "D:\ProgramData\Anaconda3\envs\website\lib\site-packages\rest_framework\views.py", line 506, in dispatch
    response = handler(request, *args, **kwargs)
  File "D:\ProgramData\Anaconda3\envs\website\lib\site-packages\rest_framework\mixins.py", line 19, in create
    self.perform_create(serializer)
  File "D:\Website\minzufs.cn\minzufs\identify\viewsets.py", line 57, in perform_create
    print(self.request.META.REMOTE_HOST)
AttributeError: 'dict' object has no attribute 'REMOTE_HOST'
[2022-01-12 16:54:33,223][Thread-1:10276][task_id:django.server][basehttp.py:154][ERROR]["POST /api/images/ HTTP/1.1" 500 19301]
[2022-01-12 17:08:11,807][Thread-1:13864][task_id:django.request][log.py:228][ERROR][Internal Server Error: /api/images/]
Traceback (most recent call last):
  File "D:\ProgramData\Anaconda3\envs\website\lib\site-packages\django\core\handlers\exception.py", line 34, in inner
    response = get_response(request)
  File "D:\ProgramData\Anaconda3\envs\website\lib\site-packages\django\core\handlers\base.py", line 115, in _get_response
    response = self.process_exception_by_middleware(e, request)
  File "D:\ProgramData\Anaconda3\envs\website\lib\site-packages\django\core\handlers\base.py", line 113, in _get_response
    response = wrapped_callback(request, *callback_args, **callback_kwargs)
  File "D:\ProgramData\Anaconda3\envs\website\lib\site-packages\django\views\decorators\csrf.py", line 54, in wrapped_view
    return view_func(*args, **kwargs)
  File "D:\ProgramData\Anaconda3\envs\website\lib\site-packages\rest_framework\viewsets.py", line 125, in view
    return self.dispatch(request, *args, **kwargs)
  File "D:\ProgramData\Anaconda3\envs\website\lib\site-packages\rest_framework\views.py", line 509, in dispatch
    response = self.handle_exception(exc)
  File "D:\ProgramData\Anaconda3\envs\website\lib\site-packages\rest_framework\views.py", line 469, in handle_exception
    self.raise_uncaught_exception(exc)
  File "D:\ProgramData\Anaconda3\envs\website\lib\site-packages\rest_framework\views.py", line 480, in raise_uncaught_exception
    raise exc
  File "D:\ProgramData\Anaconda3\envs\website\lib\site-packages\rest_framework\views.py", line 506, in dispatch
    response = handler(request, *args, **kwargs)
  File "D:\ProgramData\Anaconda3\envs\website\lib\site-packages\rest_framework\mixins.py", line 19, in create
    self.perform_create(serializer)
  File "D:\Website\minzufs.cn\minzufs\identify\viewsets.py", line 57, in perform_create
    print(self.request.data.headers)
AttributeError: 'QueryDict' object has no attribute 'headers'
[2022-01-12 17:08:11,809][Thread-1:13864][task_id:django.server][basehttp.py:154][ERROR]["POST /api/images/ HTTP/1.1" 500 19299]
[2022-01-12 17:11:51,593][Thread-1:9872][task_id:django.request][log.py:228][ERROR][Internal Server Error: /api/images/]
Traceback (most recent call last):
  File "D:\ProgramData\Anaconda3\envs\website\lib\site-packages\django\core\handlers\exception.py", line 34, in inner
    response = get_response(request)
  File "D:\ProgramData\Anaconda3\envs\website\lib\site-packages\django\core\handlers\base.py", line 115, in _get_response
    response = self.process_exception_by_middleware(e, request)
  File "D:\ProgramData\Anaconda3\envs\website\lib\site-packages\django\core\handlers\base.py", line 113, in _get_response
    response = wrapped_callback(request, *callback_args, **callback_kwargs)
  File "D:\ProgramData\Anaconda3\envs\website\lib\site-packages\django\views\decorators\csrf.py", line 54, in wrapped_view
    return view_func(*args, **kwargs)
  File "D:\ProgramData\Anaconda3\envs\website\lib\site-packages\rest_framework\viewsets.py", line 125, in view
    return self.dispatch(request, *args, **kwargs)
  File "D:\ProgramData\Anaconda3\envs\website\lib\site-packages\rest_framework\views.py", line 509, in dispatch
    response = self.handle_exception(exc)
  File "D:\ProgramData\Anaconda3\envs\website\lib\site-packages\rest_framework\views.py", line 469, in handle_exception
    self.raise_uncaught_exception(exc)
  File "D:\ProgramData\Anaconda3\envs\website\lib\site-packages\rest_framework\views.py", line 480, in raise_uncaught_exception
    raise exc
  File "D:\ProgramData\Anaconda3\envs\website\lib\site-packages\rest_framework\views.py", line 506, in dispatch
    response = handler(request, *args, **kwargs)
  File "D:\ProgramData\Anaconda3\envs\website\lib\site-packages\rest_framework\mixins.py", line 19, in create
    self.perform_create(serializer)
  File "D:\Website\minzufs.cn\minzufs\identify\viewsets.py", line 57, in perform_create
    print(self.request.data.getQueryString())
AttributeError: 'QueryDict' object has no attribute 'getQueryString'
[2022-01-12 17:11:51,595][Thread-1:9872][task_id:django.server][basehttp.py:154][ERROR]["POST /api/images/ HTTP/1.1" 500 19322]
[2022-01-12 17:12:04,201][Thread-1:1332][task_id:django.request][log.py:228][ERROR][Internal Server Error: /api/images/]
Traceback (most recent call last):
  File "D:\ProgramData\Anaconda3\envs\website\lib\site-packages\rest_framework\request.py", line 416, in __getattr__
    return getattr(self._request, attr)
AttributeError: 'WSGIRequest' object has no attribute 'getQueryString'

During handling of the above exception, another exception occurred:

Traceback (most recent call last):
  File "D:\ProgramData\Anaconda3\envs\website\lib\site-packages\django\core\handlers\exception.py", line 34, in inner
    response = get_response(request)
  File "D:\ProgramData\Anaconda3\envs\website\lib\site-packages\django\core\handlers\base.py", line 115, in _get_response
    response = self.process_exception_by_middleware(e, request)
  File "D:\ProgramData\Anaconda3\envs\website\lib\site-packages\django\core\handlers\base.py", line 113, in _get_response
    response = wrapped_callback(request, *callback_args, **callback_kwargs)
  File "D:\ProgramData\Anaconda3\envs\website\lib\site-packages\django\views\decorators\csrf.py", line 54, in wrapped_view
    return view_func(*args, **kwargs)
  File "D:\ProgramData\Anaconda3\envs\website\lib\site-packages\rest_framework\viewsets.py", line 125, in view
    return self.dispatch(request, *args, **kwargs)
  File "D:\ProgramData\Anaconda3\envs\website\lib\site-packages\rest_framework\views.py", line 509, in dispatch
    response = self.handle_exception(exc)
  File "D:\ProgramData\Anaconda3\envs\website\lib\site-packages\rest_framework\views.py", line 469, in handle_exception
    self.raise_uncaught_exception(exc)
  File "D:\ProgramData\Anaconda3\envs\website\lib\site-packages\rest_framework\views.py", line 480, in raise_uncaught_exception
    raise exc
  File "D:\ProgramData\Anaconda3\envs\website\lib\site-packages\rest_framework\views.py", line 506, in dispatch
    response = handler(request, *args, **kwargs)
  File "D:\ProgramData\Anaconda3\envs\website\lib\site-packages\rest_framework\mixins.py", line 19, in create
    self.perform_create(serializer)
  File "D:\Website\minzufs.cn\minzufs\identify\viewsets.py", line 57, in perform_create
    print(self.request.getQueryString())
  File "D:\ProgramData\Anaconda3\envs\website\lib\site-packages\rest_framework\request.py", line 418, in __getattr__
    return self.__getattribute__(attr)
AttributeError: 'Request' object has no attribute 'getQueryString'
[2022-01-12 17:12:04,205][Thread-1:1332][task_id:django.server][basehttp.py:154][ERROR]["POST /api/images/ HTTP/1.1" 500 19758]
[2022-01-12 17:13:58,911][Thread-1:8836][task_id:django.request][log.py:228][ERROR][Internal Server Error: /api/images/]
Traceback (most recent call last):
  File "D:\ProgramData\Anaconda3\envs\website\lib\site-packages\django\core\handlers\exception.py", line 34, in inner
    response = get_response(request)
  File "D:\ProgramData\Anaconda3\envs\website\lib\site-packages\django\core\handlers\base.py", line 115, in _get_response
    response = self.process_exception_by_middleware(e, request)
  File "D:\ProgramData\Anaconda3\envs\website\lib\site-packages\django\core\handlers\base.py", line 113, in _get_response
    response = wrapped_callback(request, *callback_args, **callback_kwargs)
  File "D:\ProgramData\Anaconda3\envs\website\lib\site-packages\django\views\decorators\csrf.py", line 54, in wrapped_view
    return view_func(*args, **kwargs)
  File "D:\ProgramData\Anaconda3\envs\website\lib\site-packages\rest_framework\viewsets.py", line 125, in view
    return self.dispatch(request, *args, **kwargs)
  File "D:\ProgramData\Anaconda3\envs\website\lib\site-packages\rest_framework\views.py", line 509, in dispatch
    response = self.handle_exception(exc)
  File "D:\ProgramData\Anaconda3\envs\website\lib\site-packages\rest_framework\views.py", line 469, in handle_exception
    self.raise_uncaught_exception(exc)
  File "D:\ProgramData\Anaconda3\envs\website\lib\site-packages\rest_framework\views.py", line 480, in raise_uncaught_exception
    raise exc
  File "D:\ProgramData\Anaconda3\envs\website\lib\site-packages\rest_framework\views.py", line 506, in dispatch
    response = handler(request, *args, **kwargs)
  File "D:\ProgramData\Anaconda3\envs\website\lib\site-packages\rest_framework\mixins.py", line 19, in create
    self.perform_create(serializer)
  File "D:\Website\minzufs.cn\minzufs\identify\viewsets.py", line 57, in perform_create
    print(json.loads(self.request.data))
NameError: name 'json' is not defined
[2022-01-12 17:13:58,913][Thread-1:8836][task_id:django.server][basehttp.py:154][ERROR]["POST /api/images/ HTTP/1.1" 500 19255]
[2022-01-12 17:14:54,891][Thread-1:13612][task_id:django.request][log.py:228][ERROR][Internal Server Error: /api/images/]
Traceback (most recent call last):
  File "D:\ProgramData\Anaconda3\envs\website\lib\site-packages\rest_framework\request.py", line 416, in __getattr__
    return getattr(self._request, attr)
AttributeError: 'WSGIRequest' object has no attribute 'json'

During handling of the above exception, another exception occurred:

Traceback (most recent call last):
  File "D:\ProgramData\Anaconda3\envs\website\lib\site-packages\django\core\handlers\exception.py", line 34, in inner
    response = get_response(request)
  File "D:\ProgramData\Anaconda3\envs\website\lib\site-packages\django\core\handlers\base.py", line 115, in _get_response
    response = self.process_exception_by_middleware(e, request)
  File "D:\ProgramData\Anaconda3\envs\website\lib\site-packages\django\core\handlers\base.py", line 113, in _get_response
    response = wrapped_callback(request, *callback_args, **callback_kwargs)
  File "D:\ProgramData\Anaconda3\envs\website\lib\site-packages\django\views\decorators\csrf.py", line 54, in wrapped_view
    return view_func(*args, **kwargs)
  File "D:\ProgramData\Anaconda3\envs\website\lib\site-packages\rest_framework\viewsets.py", line 125, in view
    return self.dispatch(request, *args, **kwargs)
  File "D:\ProgramData\Anaconda3\envs\website\lib\site-packages\rest_framework\views.py", line 509, in dispatch
    response = self.handle_exception(exc)
  File "D:\ProgramData\Anaconda3\envs\website\lib\site-packages\rest_framework\views.py", line 469, in handle_exception
    self.raise_uncaught_exception(exc)
  File "D:\ProgramData\Anaconda3\envs\website\lib\site-packages\rest_framework\views.py", line 480, in raise_uncaught_exception
    raise exc
  File "D:\ProgramData\Anaconda3\envs\website\lib\site-packages\rest_framework\views.py", line 506, in dispatch
    response = handler(request, *args, **kwargs)
  File "D:\ProgramData\Anaconda3\envs\website\lib\site-packages\rest_framework\mixins.py", line 19, in create
    self.perform_create(serializer)
  File "D:\Website\minzufs.cn\minzufs\identify\viewsets.py", line 57, in perform_create
    print(self.request.json)
  File "D:\ProgramData\Anaconda3\envs\website\lib\site-packages\rest_framework\request.py", line 418, in __getattr__
    return self.__getattribute__(attr)
AttributeError: 'Request' object has no attribute 'json'
[2022-01-12 17:14:54,895][Thread-1:13612][task_id:django.server][basehttp.py:154][ERROR]["POST /api/images/ HTTP/1.1" 500 19716]
[2022-01-17 12:43:58,566][Thread-1:14900][task_id:django.request][log.py:228][ERROR][Internal Server Error: /api/images/]
Traceback (most recent call last):
  File "D:\ProgramData\Anaconda3\envs\website\lib\site-packages\django\utils\datastructures.py", line 78, in __getitem__
    list_ = super().__getitem__(key)
KeyError: 'name'

During handling of the above exception, another exception occurred:

Traceback (most recent call last):
  File "D:\ProgramData\Anaconda3\envs\website\lib\site-packages\django\core\handlers\exception.py", line 34, in inner
    response = get_response(request)
  File "D:\ProgramData\Anaconda3\envs\website\lib\site-packages\django\core\handlers\base.py", line 115, in _get_response
    response = self.process_exception_by_middleware(e, request)
  File "D:\ProgramData\Anaconda3\envs\website\lib\site-packages\django\core\handlers\base.py", line 113, in _get_response
    response = wrapped_callback(request, *callback_args, **callback_kwargs)
  File "D:\ProgramData\Anaconda3\envs\website\lib\site-packages\django\views\decorators\csrf.py", line 54, in wrapped_view
    return view_func(*args, **kwargs)
  File "D:\ProgramData\Anaconda3\envs\website\lib\site-packages\rest_framework\viewsets.py", line 125, in view
    return self.dispatch(request, *args, **kwargs)
  File "D:\ProgramData\Anaconda3\envs\website\lib\site-packages\rest_framework\views.py", line 509, in dispatch
    response = self.handle_exception(exc)
  File "D:\ProgramData\Anaconda3\envs\website\lib\site-packages\rest_framework\views.py", line 469, in handle_exception
    self.raise_uncaught_exception(exc)
  File "D:\ProgramData\Anaconda3\envs\website\lib\site-packages\rest_framework\views.py", line 480, in raise_uncaught_exception
    raise exc
  File "D:\ProgramData\Anaconda3\envs\website\lib\site-packages\rest_framework\views.py", line 506, in dispatch
    response = handler(request, *args, **kwargs)
  File "D:\ProgramData\Anaconda3\envs\website\lib\site-packages\rest_framework\mixins.py", line 19, in create
    self.perform_create(serializer)
  File "D:\Website\minzufs.cn\minzufs\identify\viewsets.py", line 57, in perform_create
    print(self.request.query_params['name'])
  File "D:\ProgramData\Anaconda3\envs\website\lib\site-packages\django\utils\datastructures.py", line 80, in __getitem__
    raise MultiValueDictKeyError(key)
django.utils.datastructures.MultiValueDictKeyError: 'name'
[2022-01-17 12:43:58,586][Thread-1:14900][task_id:django.server][basehttp.py:154][ERROR]["POST /api/images/ HTTP/1.1" 500 19944]
[2022-01-17 12:46:06,321][Thread-1:13624][task_id:django.request][log.py:228][ERROR][Internal Server Error: /api/images/]
Traceback (most recent call last):
  File "D:\ProgramData\Anaconda3\envs\website\lib\site-packages\django\utils\datastructures.py", line 78, in __getitem__
    list_ = super().__getitem__(key)
KeyError: 'id'

During handling of the above exception, another exception occurred:

Traceback (most recent call last):
  File "D:\ProgramData\Anaconda3\envs\website\lib\site-packages\django\core\handlers\exception.py", line 34, in inner
    response = get_response(request)
  File "D:\ProgramData\Anaconda3\envs\website\lib\site-packages\django\core\handlers\base.py", line 115, in _get_response
    response = self.process_exception_by_middleware(e, request)
  File "D:\ProgramData\Anaconda3\envs\website\lib\site-packages\django\core\handlers\base.py", line 113, in _get_response
    response = wrapped_callback(request, *callback_args, **callback_kwargs)
  File "D:\ProgramData\Anaconda3\envs\website\lib\site-packages\django\views\decorators\csrf.py", line 54, in wrapped_view
    return view_func(*args, **kwargs)
  File "D:\ProgramData\Anaconda3\envs\website\lib\site-packages\rest_framework\viewsets.py", line 125, in view
    return self.dispatch(request, *args, **kwargs)
  File "D:\ProgramData\Anaconda3\envs\website\lib\site-packages\rest_framework\views.py", line 509, in dispatch
    response = self.handle_exception(exc)
  File "D:\ProgramData\Anaconda3\envs\website\lib\site-packages\rest_framework\views.py", line 469, in handle_exception
    self.raise_uncaught_exception(exc)
  File "D:\ProgramData\Anaconda3\envs\website\lib\site-packages\rest_framework\views.py", line 480, in raise_uncaught_exception
    raise exc
  File "D:\ProgramData\Anaconda3\envs\website\lib\site-packages\rest_framework\views.py", line 506, in dispatch
    response = handler(request, *args, **kwargs)
  File "D:\ProgramData\Anaconda3\envs\website\lib\site-packages\rest_framework\mixins.py", line 19, in create
    self.perform_create(serializer)
  File "D:\Website\minzufs.cn\minzufs\identify\viewsets.py", line 57, in perform_create
    print(self.request.query_params['id'])
  File "D:\ProgramData\Anaconda3\envs\website\lib\site-packages\django\utils\datastructures.py", line 80, in __getitem__
    raise MultiValueDictKeyError(key)
django.utils.datastructures.MultiValueDictKeyError: 'id'
[2022-01-17 12:46:06,323][Thread-1:13624][task_id:django.server][basehttp.py:154][ERROR]["POST /api/images/ HTTP/1.1" 500 19936]
[2022-02-28 02:59:48,335][Thread-7:19272][task_id:django.request][log.py:228][ERROR][Internal Server Error: /api/images/]
Traceback (most recent call last):
  File "D:\ProgramData\Anaconda3\envs\website\lib\site-packages\django\core\handlers\exception.py", line 34, in inner
    response = get_response(request)
  File "D:\ProgramData\Anaconda3\envs\website\lib\site-packages\django\core\handlers\base.py", line 115, in _get_response
    response = self.process_exception_by_middleware(e, request)
  File "D:\ProgramData\Anaconda3\envs\website\lib\site-packages\django\core\handlers\base.py", line 113, in _get_response
    response = wrapped_callback(request, *callback_args, **callback_kwargs)
  File "D:\ProgramData\Anaconda3\envs\website\lib\site-packages\django\views\decorators\csrf.py", line 54, in wrapped_view
    return view_func(*args, **kwargs)
  File "D:\ProgramData\Anaconda3\envs\website\lib\site-packages\rest_framework\viewsets.py", line 125, in view
    return self.dispatch(request, *args, **kwargs)
  File "D:\ProgramData\Anaconda3\envs\website\lib\site-packages\rest_framework\views.py", line 509, in dispatch
    response = self.handle_exception(exc)
  File "D:\ProgramData\Anaconda3\envs\website\lib\site-packages\rest_framework\views.py", line 469, in handle_exception
    self.raise_uncaught_exception(exc)
  File "D:\ProgramData\Anaconda3\envs\website\lib\site-packages\rest_framework\views.py", line 480, in raise_uncaught_exception
    raise exc
  File "D:\ProgramData\Anaconda3\envs\website\lib\site-packages\rest_framework\views.py", line 506, in dispatch
    response = handler(request, *args, **kwargs)
  File "D:\ProgramData\Anaconda3\envs\website\lib\site-packages\rest_framework\mixins.py", line 19, in create
    self.perform_create(serializer)
  File "D:\Website\minzufs.cn\minzufs\identify\viewsets.py", line 62, in perform_create
    nation1, nation2, nation3, dst, time_consuming = batch_rename.rename()
  File "D:\Website\minzufs.cn\minzufs\identify\rename.py", line 11, in rename
    file_list = os.listdir(self.path)  # 获取文件路径
FileNotFoundError: [WinError 3] 系统找不到指定的路径。: './media/upload_images/'
[2022-02-28 02:59:48,364][Thread-7:19272][task_id:django.server][basehttp.py:154][ERROR]["POST /api/images/ HTTP/1.1" 500 19794]
[2022-02-28 03:00:37,805][Thread-2:15960][task_id:django.request][log.py:228][ERROR][Internal Server Error: /api/images/]
Traceback (most recent call last):
  File "D:\ProgramData\Anaconda3\envs\website\lib\site-packages\django\core\handlers\exception.py", line 34, in inner
    response = get_response(request)
  File "D:\ProgramData\Anaconda3\envs\website\lib\site-packages\django\core\handlers\base.py", line 115, in _get_response
    response = self.process_exception_by_middleware(e, request)
  File "D:\ProgramData\Anaconda3\envs\website\lib\site-packages\django\core\handlers\base.py", line 113, in _get_response
    response = wrapped_callback(request, *callback_args, **callback_kwargs)
  File "D:\ProgramData\Anaconda3\envs\website\lib\site-packages\django\views\decorators\csrf.py", line 54, in wrapped_view
    return view_func(*args, **kwargs)
  File "D:\ProgramData\Anaconda3\envs\website\lib\site-packages\rest_framework\viewsets.py", line 125, in view
    return self.dispatch(request, *args, **kwargs)
  File "D:\ProgramData\Anaconda3\envs\website\lib\site-packages\rest_framework\views.py", line 509, in dispatch
    response = self.handle_exception(exc)
  File "D:\ProgramData\Anaconda3\envs\website\lib\site-packages\rest_framework\views.py", line 469, in handle_exception
    self.raise_uncaught_exception(exc)
  File "D:\ProgramData\Anaconda3\envs\website\lib\site-packages\rest_framework\views.py", line 480, in raise_uncaught_exception
    raise exc
  File "D:\ProgramData\Anaconda3\envs\website\lib\site-packages\rest_framework\views.py", line 506, in dispatch
    response = handler(request, *args, **kwargs)
  File "D:\ProgramData\Anaconda3\envs\website\lib\site-packages\rest_framework\mixins.py", line 19, in create
    self.perform_create(serializer)
  File "D:\Website\minzufs.cn\minzufs\identify\viewsets.py", line 62, in perform_create
    nation1, nation2, nation3, dst, time_consuming = batch_rename.rename()
  File "D:\Website\minzufs.cn\minzufs\identify\rename.py", line 11, in rename
    file_list = os.listdir(self.path)  # 获取文件路径
FileNotFoundError: [WinError 3] 系统找不到指定的路径。: './media/upload_images/'
[2022-02-28 03:00:37,807][Thread-2:15960][task_id:django.server][basehttp.py:154][ERROR]["POST /api/images/ HTTP/1.1" 500 19877]
[2022-03-11 23:32:26,506][Thread-1:6504][task_id:django.request][log.py:228][ERROR][Internal Server Error: /api/images/]
Traceback (most recent call last):
  File "D:\ProgramData\Anaconda3\envs\website\lib\site-packages\django\core\handlers\exception.py", line 34, in inner
    response = get_response(request)
  File "D:\ProgramData\Anaconda3\envs\website\lib\site-packages\django\core\handlers\base.py", line 115, in _get_response
    response = self.process_exception_by_middleware(e, request)
  File "D:\ProgramData\Anaconda3\envs\website\lib\site-packages\django\core\handlers\base.py", line 113, in _get_response
    response = wrapped_callback(request, *callback_args, **callback_kwargs)
  File "D:\ProgramData\Anaconda3\envs\website\lib\site-packages\django\views\decorators\csrf.py", line 54, in wrapped_view
    return view_func(*args, **kwargs)
  File "D:\ProgramData\Anaconda3\envs\website\lib\site-packages\rest_framework\viewsets.py", line 125, in view
    return self.dispatch(request, *args, **kwargs)
  File "D:\ProgramData\Anaconda3\envs\website\lib\site-packages\rest_framework\views.py", line 509, in dispatch
    response = self.handle_exception(exc)
  File "D:\ProgramData\Anaconda3\envs\website\lib\site-packages\rest_framework\views.py", line 469, in handle_exception
    self.raise_uncaught_exception(exc)
  File "D:\ProgramData\Anaconda3\envs\website\lib\site-packages\rest_framework\views.py", line 480, in raise_uncaught_exception
    raise exc
  File "D:\ProgramData\Anaconda3\envs\website\lib\site-packages\rest_framework\views.py", line 506, in dispatch
    response = handler(request, *args, **kwargs)
  File "D:\ProgramData\Anaconda3\envs\website\lib\site-packages\rest_framework\mixins.py", line 19, in create
    self.perform_create(serializer)
  File "D:\Website\minzufs.cn\minzufs\identify\viewsets.py", line 62, in perform_create
    nation1, nation2, nation3, dst, time_consuming = batch_rename.rename()
  File "D:\Website\minzufs.cn\minzufs\identify\rename.py", line 11, in rename
    file_list = os.listdir(self.path)  # 获取文件路径
FileNotFoundError: [WinError 3] 系统找不到指定的路径。: './media/upload_images/'
[2022-03-11 23:32:26,522][Thread-1:6504][task_id:django.server][basehttp.py:154][ERROR]["POST /api/images/ HTTP/1.1" 500 19897]
[2022-03-12 00:51:18,928][Thread-1:15020][task_id:django.request][log.py:228][ERROR][Internal Server Error: /api/images/]
Traceback (most recent call last):
  File "D:\ProgramData\Anaconda3\envs\website\lib\site-packages\django\core\handlers\exception.py", line 34, in inner
    response = get_response(request)
  File "D:\ProgramData\Anaconda3\envs\website\lib\site-packages\django\core\handlers\base.py", line 115, in _get_response
    response = self.process_exception_by_middleware(e, request)
  File "D:\ProgramData\Anaconda3\envs\website\lib\site-packages\django\core\handlers\base.py", line 113, in _get_response
    response = wrapped_callback(request, *callback_args, **callback_kwargs)
  File "D:\ProgramData\Anaconda3\envs\website\lib\site-packages\django\views\decorators\csrf.py", line 54, in wrapped_view
    return view_func(*args, **kwargs)
  File "D:\ProgramData\Anaconda3\envs\website\lib\site-packages\rest_framework\viewsets.py", line 125, in view
    return self.dispatch(request, *args, **kwargs)
  File "D:\ProgramData\Anaconda3\envs\website\lib\site-packages\rest_framework\views.py", line 509, in dispatch
    response = self.handle_exception(exc)
  File "D:\ProgramData\Anaconda3\envs\website\lib\site-packages\rest_framework\views.py", line 469, in handle_exception
    self.raise_uncaught_exception(exc)
  File "D:\ProgramData\Anaconda3\envs\website\lib\site-packages\rest_framework\views.py", line 480, in raise_uncaught_exception
    raise exc
  File "D:\ProgramData\Anaconda3\envs\website\lib\site-packages\rest_framework\views.py", line 506, in dispatch
    response = handler(request, *args, **kwargs)
  File "D:\ProgramData\Anaconda3\envs\website\lib\site-packages\rest_framework\mixins.py", line 19, in create
    self.perform_create(serializer)
  File "D:\Website\minzufs.cn\minzufs\identify\viewsets.py", line 62, in perform_create
    nation1, nation2, nation3, dst, time_consuming = batch_rename.rename()
  File "D:\Website\minzufs.cn\minzufs\identify\rename.py", line 11, in rename
    file_list = os.listdir(self.path)  # 获取文件路径
FileNotFoundError: [WinError 3] 系统找不到指定的路径。: './media/upload_images/'
[2022-03-12 00:51:18,931][Thread-1:15020][task_id:django.server][basehttp.py:154][ERROR]["POST /api/images/ HTTP/1.1" 500 19896]
[2022-03-12 00:53:06,792][Thread-1:11280][task_id:django.request][log.py:228][ERROR][Internal Server Error: /api/images/]
Traceback (most recent call last):
  File "D:\ProgramData\Anaconda3\envs\website\lib\site-packages\django\core\handlers\exception.py", line 34, in inner
    response = get_response(request)
  File "D:\ProgramData\Anaconda3\envs\website\lib\site-packages\django\core\handlers\base.py", line 115, in _get_response
    response = self.process_exception_by_middleware(e, request)
  File "D:\ProgramData\Anaconda3\envs\website\lib\site-packages\django\core\handlers\base.py", line 113, in _get_response
    response = wrapped_callback(request, *callback_args, **callback_kwargs)
  File "D:\ProgramData\Anaconda3\envs\website\lib\site-packages\django\views\decorators\csrf.py", line 54, in wrapped_view
    return view_func(*args, **kwargs)
  File "D:\ProgramData\Anaconda3\envs\website\lib\site-packages\rest_framework\viewsets.py", line 125, in view
    return self.dispatch(request, *args, **kwargs)
  File "D:\ProgramData\Anaconda3\envs\website\lib\site-packages\rest_framework\views.py", line 509, in dispatch
    response = self.handle_exception(exc)
  File "D:\ProgramData\Anaconda3\envs\website\lib\site-packages\rest_framework\views.py", line 469, in handle_exception
    self.raise_uncaught_exception(exc)
  File "D:\ProgramData\Anaconda3\envs\website\lib\site-packages\rest_framework\views.py", line 480, in raise_uncaught_exception
    raise exc
  File "D:\ProgramData\Anaconda3\envs\website\lib\site-packages\rest_framework\views.py", line 506, in dispatch
    response = handler(request, *args, **kwargs)
  File "D:\ProgramData\Anaconda3\envs\website\lib\site-packages\rest_framework\mixins.py", line 19, in create
    self.perform_create(serializer)
  File "D:\Website\minzufs.cn\minzufs\identify\viewsets.py", line 62, in perform_create
    nation1, nation2, nation3, dst, time_consuming = batch_rename.rename()
  File "D:\Website\minzufs.cn\minzufs\identify\rename.py", line 11, in rename
    file_list = os.listdir(self.path)  # 获取文件路径
FileNotFoundError: [WinError 3] 系统找不到指定的路径。: '../media/upload_images/'
[2022-03-12 00:53:06,793][Thread-1:11280][task_id:django.server][basehttp.py:154][ERROR]["POST /api/images/ HTTP/1.1" 500 19898]
[2022-03-12 00:53:36,894][Thread-1:16184][task_id:django.request][log.py:228][ERROR][Internal Server Error: /api/images/]
Traceback (most recent call last):
  File "D:\ProgramData\Anaconda3\envs\website\lib\site-packages\django\core\handlers\exception.py", line 34, in inner
    response = get_response(request)
  File "D:\ProgramData\Anaconda3\envs\website\lib\site-packages\django\core\handlers\base.py", line 115, in _get_response
    response = self.process_exception_by_middleware(e, request)
  File "D:\ProgramData\Anaconda3\envs\website\lib\site-packages\django\core\handlers\base.py", line 113, in _get_response
    response = wrapped_callback(request, *callback_args, **callback_kwargs)
  File "D:\ProgramData\Anaconda3\envs\website\lib\site-packages\django\views\decorators\csrf.py", line 54, in wrapped_view
    return view_func(*args, **kwargs)
  File "D:\ProgramData\Anaconda3\envs\website\lib\site-packages\rest_framework\viewsets.py", line 125, in view
    return self.dispatch(request, *args, **kwargs)
  File "D:\ProgramData\Anaconda3\envs\website\lib\site-packages\rest_framework\views.py", line 509, in dispatch
    response = self.handle_exception(exc)
  File "D:\ProgramData\Anaconda3\envs\website\lib\site-packages\rest_framework\views.py", line 469, in handle_exception
    self.raise_uncaught_exception(exc)
  File "D:\ProgramData\Anaconda3\envs\website\lib\site-packages\rest_framework\views.py", line 480, in raise_uncaught_exception
    raise exc
  File "D:\ProgramData\Anaconda3\envs\website\lib\site-packages\rest_framework\views.py", line 506, in dispatch
    response = handler(request, *args, **kwargs)
  File "D:\ProgramData\Anaconda3\envs\website\lib\site-packages\rest_framework\mixins.py", line 19, in create
    self.perform_create(serializer)
  File "D:\Website\minzufs.cn\minzufs\identify\viewsets.py", line 62, in perform_create
    nation1, nation2, nation3, dst, time_consuming = batch_rename.rename()
  File "D:\Website\minzufs.cn\minzufs\identify\rename.py", line 11, in rename
    file_list = os.listdir(self.path)  # 获取文件路径
FileNotFoundError: [WinError 3] 系统找不到指定的路径。: './media/upload_images/'
[2022-03-12 00:53:36,895][Thread-1:16184][task_id:django.server][basehttp.py:154][ERROR]["POST /api/images/ HTTP/1.1" 500 19896]
[2022-03-19 00:49:49,176][Thread-3:5528][task_id:django.request][log.py:228][ERROR][Internal Server Error: /xadmin/xadmin/userwidget/add/]
Traceback (most recent call last):
  File "D:\ProgramData\Anaconda3\envs\website\lib\site-packages\django\core\handlers\exception.py", line 34, in inner
    response = get_response(request)
  File "D:\ProgramData\Anaconda3\envs\website\lib\site-packages\django\core\handlers\base.py", line 145, in _get_response
    response = self.process_exception_by_middleware(e, request)
  File "D:\ProgramData\Anaconda3\envs\website\lib\site-packages\django\core\handlers\base.py", line 143, in _get_response
    response = response.render()
  File "D:\ProgramData\Anaconda3\envs\website\lib\site-packages\django\template\response.py", line 106, in render
    self.content = self.rendered_content
  File "D:\ProgramData\Anaconda3\envs\website\lib\site-packages\django\template\response.py", line 83, in rendered_content
    content = template.render(context, self._request)
  File "D:\ProgramData\Anaconda3\envs\website\lib\site-packages\django\template\backends\django.py", line 61, in render
    return self.template.render(context)
  File "D:\ProgramData\Anaconda3\envs\website\lib\site-packages\django\template\base.py", line 171, in render
    return self._render(context)
  File "D:\ProgramData\Anaconda3\envs\website\lib\site-packages\django\template\base.py", line 163, in _render
    return self.nodelist.render(context)
  File "D:\ProgramData\Anaconda3\envs\website\lib\site-packages\django\template\base.py", line 937, in render
    bit = node.render_annotated(context)
  File "D:\ProgramData\Anaconda3\envs\website\lib\site-packages\django\template\base.py", line 904, in render_annotated
    return self.render(context)
  File "D:\ProgramData\Anaconda3\envs\website\lib\site-packages\django\template\loader_tags.py", line 150, in render
    return compiled_parent._render(context)
  File "D:\ProgramData\Anaconda3\envs\website\lib\site-packages\django\template\base.py", line 163, in _render
    return self.nodelist.render(context)
  File "D:\ProgramData\Anaconda3\envs\website\lib\site-packages\django\template\base.py", line 937, in render
    bit = node.render_annotated(context)
  File "D:\ProgramData\Anaconda3\envs\website\lib\site-packages\django\template\base.py", line 904, in render_annotated
    return self.render(context)
  File "D:\ProgramData\Anaconda3\envs\website\lib\site-packages\django\template\loader_tags.py", line 150, in render
    return compiled_parent._render(context)
  File "D:\ProgramData\Anaconda3\envs\website\lib\site-packages\django\template\base.py", line 163, in _render
    return self.nodelist.render(context)
  File "D:\ProgramData\Anaconda3\envs\website\lib\site-packages\django\template\base.py", line 937, in render
    bit = node.render_annotated(context)
  File "D:\ProgramData\Anaconda3\envs\website\lib\site-packages\django\template\base.py", line 904, in render_annotated
    return self.render(context)
  File "D:\ProgramData\Anaconda3\envs\website\lib\site-packages\django\template\loader_tags.py", line 62, in render
    result = block.nodelist.render(context)
  File "D:\ProgramData\Anaconda3\envs\website\lib\site-packages\django\template\base.py", line 937, in render
    bit = node.render_annotated(context)
  File "D:\ProgramData\Anaconda3\envs\website\lib\site-packages\django\template\base.py", line 904, in render_annotated
    return self.render(context)
  File "D:\ProgramData\Anaconda3\envs\website\lib\site-packages\django\template\loader_tags.py", line 62, in render
    result = block.nodelist.render(context)
  File "D:\ProgramData\Anaconda3\envs\website\lib\site-packages\django\template\base.py", line 937, in render
    bit = node.render_annotated(context)
  File "D:\ProgramData\Anaconda3\envs\website\lib\site-packages\django\template\base.py", line 904, in render_annotated
    return self.render(context)
  File "D:\ProgramData\Anaconda3\envs\website\lib\site-packages\crispy_forms\templatetags\crispy_forms_tags.py", line 204, in render
    c = self.get_render(context).flatten()
  File "D:\ProgramData\Anaconda3\envs\website\lib\site-packages\crispy_forms\templatetags\crispy_forms_tags.py", line 121, in get_render
    actual_form, node_context, template_pack=self.template_pack
  File "D:\ProgramData\Anaconda3\envs\website\lib\site-packages\crispy_forms\helper.py", line 301, in render_layout
    html = self.layout.render(form, self.form_style, context, template_pack=template_pack)
  File "D:\ProgramData\Anaconda3\envs\website\lib\site-packages\crispy_forms\layout.py", line 135, in render
    return self.get_rendered_fields(form, form_style, context, template_pack, **kwargs)
  File "D:\ProgramData\Anaconda3\envs\website\lib\site-packages\crispy_forms\layout.py", line 98, in get_rendered_fields
    for field in self.fields
  File "D:\ProgramData\Anaconda3\envs\website\lib\site-packages\crispy_forms\layout.py", line 98, in <genexpr>
    for field in self.fields
  File "D:\ProgramData\Anaconda3\envs\website\lib\site-packages\crispy_forms\utils.py", line 66, in render_field
    return field.render(form, form_style, context, template_pack=template_pack)
  File "D:\ProgramData\Anaconda3\envs\website\lib\site-packages\crispy_forms\layout.py", line 367, in render
    fields = self.get_rendered_fields(form, form_style, context, template_pack, **kwargs)
  File "D:\ProgramData\Anaconda3\envs\website\lib\site-packages\crispy_forms\layout.py", line 98, in get_rendered_fields
    for field in self.fields
  File "D:\ProgramData\Anaconda3\envs\website\lib\site-packages\crispy_forms\layout.py", line 98, in <genexpr>
    for field in self.fields
  File "D:\ProgramData\Anaconda3\envs\website\lib\site-packages\crispy_forms\utils.py", line 66, in render_field
    return field.render(form, form_style, context, template_pack=template_pack)
  File "D:\ProgramData\Anaconda3\envs\website\lib\site-packages\crispy_forms\layout.py", line 367, in render
    fields = self.get_rendered_fields(form, form_style, context, template_pack, **kwargs)
  File "D:\ProgramData\Anaconda3\envs\website\lib\site-packages\crispy_forms\layout.py", line 98, in get_rendered_fields
    for field in self.fields
  File "D:\ProgramData\Anaconda3\envs\website\lib\site-packages\crispy_forms\layout.py", line 98, in <genexpr>
    for field in self.fields
  File "D:\ProgramData\Anaconda3\envs\website\lib\site-packages\crispy_forms\utils.py", line 66, in render_field
    return field.render(form, form_style, context, template_pack=template_pack)
  File "D:\ProgramData\Anaconda3\envs\website\lib\site-packages\crispy_forms\layout.py", line 289, in render
    fields = self.get_rendered_fields(form, form_style, context, template_pack, **kwargs)
  File "D:\ProgramData\Anaconda3\envs\website\lib\site-packages\crispy_forms\layout.py", line 98, in get_rendered_fields
    for field in self.fields
  File "D:\ProgramData\Anaconda3\envs\website\lib\site-packages\crispy_forms\layout.py", line 98, in <genexpr>
    for field in self.fields
  File "D:\ProgramData\Anaconda3\envs\website\lib\site-packages\crispy_forms\utils.py", line 139, in render_field
    html = template.render(context)
  File "D:\ProgramData\Anaconda3\envs\website\lib\site-packages\django\template\backends\django.py", line 61, in render
    return self.template.render(context)
  File "D:\ProgramData\Anaconda3\envs\website\lib\site-packages\django\template\base.py", line 171, in render
    return self._render(context)
  File "D:\ProgramData\Anaconda3\envs\website\lib\site-packages\django\template\base.py", line 163, in _render
    return self.nodelist.render(context)
  File "D:\ProgramData\Anaconda3\envs\website\lib\site-packages\django\template\base.py", line 937, in render
    bit = node.render_annotated(context)
  File "D:\ProgramData\Anaconda3\envs\website\lib\site-packages\django\template\base.py", line 904, in render_annotated
    return self.render(context)
  File "D:\ProgramData\Anaconda3\envs\website\lib\site-packages\django\template\defaulttags.py", line 309, in render
    return nodelist.render(context)
  File "D:\ProgramData\Anaconda3\envs\website\lib\site-packages\django\template\base.py", line 937, in render
    bit = node.render_annotated(context)
  File "D:\ProgramData\Anaconda3\envs\website\lib\site-packages\django\template\base.py", line 904, in render_annotated
    return self.render(context)
  File "D:\ProgramData\Anaconda3\envs\website\lib\site-packages\django\template\defaulttags.py", line 309, in render
    return nodelist.render(context)
  File "D:\ProgramData\Anaconda3\envs\website\lib\site-packages\django\template\base.py", line 937, in render
    bit = node.render_annotated(context)
  File "D:\ProgramData\Anaconda3\envs\website\lib\site-packages\django\template\base.py", line 904, in render_annotated
    return self.render(context)
  File "D:\ProgramData\Anaconda3\envs\website\lib\site-packages\django\template\defaulttags.py", line 309, in render
    return nodelist.render(context)
  File "D:\ProgramData\Anaconda3\envs\website\lib\site-packages\django\template\base.py", line 937, in render
    bit = node.render_annotated(context)
  File "D:\ProgramData\Anaconda3\envs\website\lib\site-packages\django\template\base.py", line 904, in render_annotated
    return self.render(context)
  File "D:\ProgramData\Anaconda3\envs\website\lib\site-packages\crispy_forms\templatetags\crispy_forms_field.py", line 155, in render
    return str(field)
  File "D:\ProgramData\Anaconda3\envs\website\lib\site-packages\django\utils\html.py", line 388, in <lambda>
    klass.__str__ = lambda self: mark_safe(klass_str(self))
  File "D:\ProgramData\Anaconda3\envs\website\lib\site-packages\django\forms\boundfield.py", line 33, in __str__
    return self.as_widget()
  File "D:\ProgramData\Anaconda3\envs\website\lib\site-packages\django\forms\boundfield.py", line 93, in as_widget
    renderer=self.form.renderer,
TypeError: render() got an unexpected keyword argument 'renderer'
[2022-03-19 00:49:49,198][Thread-3:5528][task_id:django.server][basehttp.py:154][ERROR]["GET /xadmin/xadmin/userwidget/add/ HTTP/1.1" 500 694388]
